Workbook
Name DATOS: Datos!$B$2:$S$17

Sheet PS1 (17)
A1: BOLETA DE PAGO | W1: EMPLEADO | X1: # AG ESSALUD | Y1: CODIGO EMPRESA
A2: EMPRESA | B2: CLARKE, MODET & CO. PERU S.A.C. | E2: R.U.C. | F2: 20256396000 | G2: MES | H2: =Detallado!R2 -> 05 | I2: AÑO | J2: =Detallado!S2 -> 2026 | K2: F. INGRESO | L2: =VLOOKUP(A6,'BD Total'!$A$2:$EZ$17,11,FALSE) -> 45740 | O2: # | P2: 1 | W2: 1007874085 | X2: 260130RRCOI9 | Y2: 07874085
E3: PERIODO | F3: =VLOOKUP($A$6,Detallado!$C:$U,16,FALSE) -> 05 | G3: DEL | H3: =VLOOKUP($A$6,Detallado!$C:$U,18,FALSE) -> 01/05/2026 | I3: AL | J3: =VLOOKUP($A$6,Detallado!$C:$U,19,FALSE) -> 46173 | K3: F. RETIRO | W3: 1040703418 | X3: 595200FCCCA8 | Y3: 40703418
W4: 1044771836 | X4: 621441RFSRR2 | Y4: 44771836
A5: CÓDIGO | B5: NOMBRES Y APELLIDOS | E5: CARGO | I5: AREA | W5: 1045191394 | X5: 322431AABAT4 | Y5: 45191394
A6: 76607245 | B6: =VLOOKUP(A6,Dev!$C$1:$D$88,2,FALSE) -> STEFFANY FELICIA CAICEDO ROSADO | E6: =VLOOKUP(A6,'BD Total'!$A$2:$EZ$18,77,FALSE) -> BECARIA | I6: =VLOOKUP(A6,'BD Total'!$A$2:$EZ$18,81,FALSE) -> FACILITES | W6: 1046129072 | X6: 628890LLCAD9 | Y6: 46129072
A7: D.N.I. | B7: CUSPP AFP | C7: # AG ESSALUD | E7: SALARIO | G7: MONEDA | I7: CODIGO EMPRESA | K7: A.F.P. | W7: 1046722547 | X7: 632311FKROJ0 | Y7: 46722547
A8: =VLOOKUP(A6,'BD Total'!$A$2:$EZ$18,2,FALSE) -> 76607245 | B8: =VLOOKUP(A6,'BD Total'!$A$2:$EZ$18,85,FALSE) -> FACILITIES | C8: =VLOOKUP(A6,$W$1:$Y$20,2,FALSE) -> N/A | E8: =VLOOKUP(A6,'BD Total'!$A$2:$EZ$18,22,FALSE) -> 1130 | G8: SOL | I8: =VLOOKUP(A6,$W$1:$Y$20,3,FALSE) -> 76607245 | K8: =VLOOKUP(A6,'BD Total'!$A$2:$EZ$18,101,FALSE) | W8: 1047924040 | X8: 641640MNERI3 | Y8: 47924040
W9: 1070165336 | X9: 640621VFCNT9 | Y9: 70165336
A10: REMUNERACIONES | E10: DESCUENTOS TRABAJADOR | I10: APORTACIONES EMPLEADOR | W10: 1070680748 | X10: 0 | Y10: 70680748
A11: CONCEPTO | C11: HORAS | D11: VALOR | E11: CONCEPTO | G11: HORAS | H11: VALOR | I11: CONCEPTO | K11: HORAS | L11: VALOR | W11: 1072251509 | X11: 631390CHTMR2 | Y11: 72251509
A12: A006 SUBVENCION ECONOMICA | C12: =SUMIF(Dev!$B:$B,CONCATENATE($A$6,A12),Dev!$L:$L) -> 216 | D12: =SUMIF(Dev!$B:$B,CONCATENATE($A$6,A12),Dev!M:M) -> 1017 | I12: APORTE A ESSALUD | K12: 0 | L12: =VLOOKUP(A6,ESSALUD!$B$1:$G$19,6,FALSE) -> 0 | W12: 1077485287 | X12: 655610ZCBIT4 | Y12: 77485287
A13: G006 VACACIONES | C13: =SUMIF(Dev!$B:$B,CONCATENATE($A$6,A13),Dev!$L:$L) -> 24 | D13: =SUMIF(Dev!$B:$B,CONCATENATE($A$6,A13),Dev!M:M) -> 113 | I13: CREDITO EPS | K13: 0 | L13: =VLOOKUP(A6,ESSALUD!$B$1:$H$19,7,FALSE) -> 0 | W13: 2001252358 | X13: 627991JMXQX0 | Y13: 001252358
W14: 42115329 | X14: FACILITIES | Y14: 42115329
W15: 42683912 | X15: 309631GHMAI4 | Y15: 42683912
W16: 72836862 | X16: 663680JMDIO1 | Y16: 72836862
W17: 76607245 | X17: N/A | Y17: 76607245
W18: 74026184 | X18: N/A | Y18: 74026184
I25: TOTAL APORTE EMPLEADOR | L25: =SUM(L12:L24) -> 0
A26: REMUNERACION TOTAL | D26: =SUM(D12:D24) -> 1130 | E26: DESCUENTOS TOTALES | H26: =SUM(H12:H24) -> 0 | I26: REMUNERACION NETA | L26: =+D26-H26 -> 1130
F36: REPRESENTANTE LEGAL | J36: RECIBI CONFORME TRABAJADOR

Sheet PS1 (16)
A1: BOLETA DE PAGO | W1: EMPLEADO | X1: # AG ESSALUD | Y1: CODIGO EMPRESA
A2: EMPRESA | B2: CLARKE, MODET & CO. PERU S.A.C. | E2: R.U.C. | F2: 20256396000 | G2: MES | H2: =Detallado!R2 -> 05 | I2: AÑO | J2: =Detallado!S2 -> 2026 | K2: F. INGRESO | L2: =VLOOKUP(A6,'BD Total'!$A$2:$EZ$17,11,FALSE) -> #N/A | O2: # | P2: 1 | W2: 1007874085 | X2: 260130RRCOI9 | Y2: 07874085
E3: PERIODO | F3: =VLOOKUP($A$6,Detallado!$C:$U,16,FALSE) -> 05 | G3: DEL | H3: =VLOOKUP($A$6,Detallado!$C:$U,18,FALSE) -> 01/05/2026 | I3: AL | J3: =VLOOKUP($A$6,Detallado!$C:$U,19,FALSE) -> 46173 | K3: F. RETIRO | W3: 1040703418 | X3: 595200FCCCA8 | Y3: 40703418
W4: 1044771836 | X4: 621441RFSRR2 | Y4: 44771836
A5: CÓDIGO | B5: NOMBRES Y APELLIDOS | E5: CARGO | I5: AREA | W5: 1045191394 | X5: 322431AABAT4 | Y5: 45191394
A6: 74026184 | B6: =VLOOKUP(A6,Dev!$C$1:$D$88,2,FALSE) -> JACKELINE TAMARA FAJARDO APOLAYA | E6: =VLOOKUP(A6,'BD Total'!$A$2:$EZ$18,77,FALSE) -> BECARIA | I6: =VLOOKUP(A6,'BD Total'!$A$2:$EZ$18,81,FALSE) -> FACILITES | W6: 1046129072 | X6: 628890LLCAD9 | Y6: 46129072
A7: D.N.I. | B7: CUSPP AFP | C7: # AG ESSALUD | E7: SALARIO | G7: MONEDA | I7: CODIGO EMPRESA | K7: A.F.P. | W7: 1046722547 | X7: 632311FKROJ0 | Y7: 46722547
A8: =VLOOKUP(A6,'BD Total'!$A$2:$EZ$18,2,FALSE) -> 74026184 | B8: =VLOOKUP(A6,'BD Total'!$A$2:$EZ$18,85,FALSE) -> FACILITIES | C8: =VLOOKUP(A6,$W$1:$Y$20,2,FALSE) -> N/A | E8: =VLOOKUP(A6,'BD Total'!$A$2:$EZ$18,22,FALSE) -> 1130 | G8: SOL | I8: =VLOOKUP(A6,$W$1:$Y$20,3,FALSE) -> 74026184 | K8: =VLOOKUP(A6,'BD Total'!$A$2:$EZ$18,101,FALSE) | W8: 1047924040 | X8: 641640MNERI3 | Y8: 47924040
W9: 1070165336 | X9: 640621VFCNT9 | Y9: 70165336
A10: REMUNERACIONES | E10: DESCUENTOS TRABAJADOR | I10: APORTACIONES EMPLEADOR | W10: 1070680748 | X10: 0 | Y10: 70680748
A11: CONCEPTO | C11: HORAS | D11: VALOR | E11: CONCEPTO | G11: HORAS | H11: VALOR | I11: CONCEPTO | K11: HORAS | L11: VALOR | W11: 1072251509 | X11: 631390CHTMR2 | Y11: 72251509
A12: A006 SUBVENCION ECONOMICA | C12: =SUMIF(Dev!$B:$B,CONCATENATE($A$6,A12),Dev!$L:$L) -> 160 | D12: =SUMIF(Dev!$B:$B,CONCATENATE($A$6,A12),Dev!M:M) -> 753.33 | I12: APORTE A ESSALUD | K12: 0 | L12: =VLOOKUP(A6,ESSALUD!$B$1:$G$19,6,FALSE) -> 0 | W12: 1077485287 | X12: 655610ZCBIT4 | Y12: 77485287
I13: CREDITO EPS | K13: 0 | L13: =VLOOKUP(A6,ESSALUD!$B$1:$H$19,7,FALSE) -> 0 | W13: 2001252358 | X13: 627991JMXQX0 | Y13: 001252358
W14: 42115329 | X14: FACILITIES | Y14: 42115329
W15: 42683912 | X15: 309631GHMAI4 | Y15: 42683912
W16: 72836862 | X16: 663680JMDIO1 | Y16: 72836862
W17: 76607245 | X17: N/A | Y17: 76607245
W18: 74026184 | X18: N/A | Y18: 74026184
I25: TOTAL APORTE EMPLEADOR | L25: =SUM(L12:L24) -> 0
A26: REMUNERACION TOTAL | D26: =SUM(D12:D24) -> 753.33 | E26: DESCUENTOS TOTALES | H26: =SUM(H12:H24) -> 0 | I26: REMUNERACION NETA | L26: =+D26-H26 -> 753.33
F36: REPRESENTANTE LEGAL | J36: RECIBI CONFORME TRABAJADOR

Sheet PS1 (15)
A1: BOLETA DE PAGO | W1: EMPLEADO | X1: # AG ESSALUD | Y1: CODIGO EMPRESA
A2: EMPRESA | B2: CLARKE, MODET & CO. PERU S.A.C. | E2: R.U.C. | F2: 20256396000 | G2: MES | H2: =Detallado!R2 -> 05 | I2: AÑO | J2: =Detallado!S2 -> 2026 | K2: F. INGRESO | L2: =VLOOKUP(A6,'BD Total'!$A$2:$EZ$17,11,FALSE) -> 45208 | O2: # | P2: 1 | W2: 1007874085 | X2: 260130RRCOI9 | Y2: 07874085
E3: PERIODO | F3: =VLOOKUP($A$6,Detallado!$C:$U,16,FALSE) -> 05 | G3: DEL | H3: =VLOOKUP($A$6,Detallado!$C:$U,18,FALSE) -> 01/05/2026 | I3: AL | J3: =VLOOKUP($A$6,Detallado!$C:$U,19,FALSE) -> 46173 | K3: F. RETIRO | W3: 1040703418 | X3: 595200FCCCA8 | Y3: 40703418
W4: 1044771836 | X4: 621441RFSRR2 | Y4: 44771836
A5: CÓDIGO | B5: NOMBRES Y APELLIDOS | E5: CARGO | I5: AREA | W5: 1045191394 | X5: 322431AABAT4 | Y5: 45191394
A6: 72836862 | B6: =VLOOKUP(A6,Dev!$C$1:$D$88,2,FALSE) -> JACKELINE NANCY MEJIA DOLORES | E6: =VLOOKUP(A6,'BD Total'!$A$2:$EZ$18,77,FALSE) -> IP PROCUREMENT SPECIALIST | I6: =VLOOKUP(A6,'BD Total'!$A$2:$EZ$18,81,FALSE) -> TRADEMARKS | W6: 1046129072 | X6: 628890LLCAD9 | Y6: 46129072
A7: D.N.I. | B7: CUSPP AFP | C7: # AG ESSALUD | E7: SALARIO | G7: MONEDA | I7: CODIGO EMPRESA | K7: A.F.P. | W7: 1046722547 | X7: 632311FKROJ0 | Y7: 46722547
A8: =VLOOKUP(A6,'BD Total'!$A$2:$EZ$18,2,FALSE) -> 72836862 | B8: =VLOOKUP(A6,'BD Total'!$A$2:$EZ$18,85,FALSE) -> 663680JMDIO1 | C8: =VLOOKUP(A6,$W$1:$Y$20,2,FALSE) -> 663680JMDIO1 | E8: =VLOOKUP(A6,'BD Total'!$A$2:$EZ$18,22,FALSE) -> 2652 | G8: SOL | I8: =VLOOKUP(A6,$W$1:$Y$20,3,FALSE) -> 72836862 | K8: =VLOOKUP(A6,'BD Total'!$A$2:$EZ$18,101,FALSE) -> INTEGRA | W8: 1047924040 | X8: 641640MNERI3 | Y8: 47924040
W9: 1070165336 | X9: 640621VFCNT9 | Y9: 70165336
A10: REMUNERACIONES | E10: DESCUENTOS TRABAJADOR | I10: APORTACIONES EMPLEADOR | W10: 1070680748 | X10: 0 | Y10: 70680748
A11: CONCEPTO | C11: HORAS | D11: VALOR | E11: CONCEPTO | G11: HORAS | H11: VALOR | I11: CONCEPTO | K11: HORAS | L11: VALOR | W11: 1072251509 | X11: 631390CHTMR2 | Y11: 72251509
A12: A000 SUELDO BASICO | C12: =SUMIF(Dev!$B:$B,CONCATENATE($A$6,A12),Dev!$L:$L) -> 168 | D12: =SUMIF(Dev!$B:$B,CONCATENATE($A$6,A12),Dev!M:M) -> 1856.4 | E12: I100 APORTE OBLIGATORIO AFP | G12: =SUMIF(Dev!$B:$B,CONCATENATE($A$6,E12),Dev!$L:$L) -> 0 | H12: =SUMIF(Dev!$B:$B,CONCATENATE($A$6,E12),Dev!N:N) -> 265.2 | I12: APORTE A ESSALUD | K12: 0 | L12: =VLOOKUP(A6,ESSALUD!$B$1:$G$19,6,FALSE) -> 179.01 | W12: 1077485287 | X12: 655610ZCBIT4 | Y12: 77485287
A13: D013 AUXILIO DE MOVILIDAD | C13: =SUMIF(Dev!$B:$B,CONCATENATE($A$6,A13),Dev!$L:$L) -> 0 | D13: =SUMIF(Dev!$B:$B,CONCATENATE($A$6,A13),Dev!M:M) -> 32 | E13: I200 SOBREVIVENCIA AFP | G13: =SUMIF(Dev!$B:$B,CONCATENATE($A$6,E13),Dev!$L:$L) -> 0 | H13: =SUMIF(Dev!$B:$B,CONCATENATE($A$6,E13),Dev!N:N) -> 36.33 | I13: CREDITO EPS | K13: 0 | L13: =VLOOKUP(A6,ESSALUD!$B$1:$H$19,7,FALSE) -> 59.67 | W13: 2001252358 | X13: 627991JMXQX0 | Y13: 001252358
A14: G006 VACACIONES | C14: =SUMIF(Dev!$B:$B,CONCATENATE($A$6,A14),Dev!$L:$L) -> 72 | D14: =SUMIF(Dev!$B:$B,CONCATENATE($A$6,A14),Dev!M:M) -> 795.6 | W14: 42115329 | X14: FACILITIES | Y14: 42115329
W15: 42683912 | X15: 309631GHMAI4 | Y15: 42683912
W16: 72836862 | X16: 663680JMDIO1 | Y16: 72836862
W17: 76607245 | X17: N/A | Y17: 76607245
W18: 74026184 | X18: N/A | Y18: 74026184
I25: TOTAL APORTE EMPLEADOR | L25: =SUM(L12:L24) -> 238.68
A26: REMUNERACION TOTAL | D26: =SUM(D12:D24) -> 2684 | E26: DESCUENTOS TOTALES | H26: =SUM(H12:H24) -> 301.53 | I26: REMUNERACION NETA | L26: =+D26-H26 -> 2382.47
F36: REPRESENTANTE LEGAL | J36: RECIBI CONFORME TRABAJADOR

Sheet PS1 (14)
A1: BOLETA DE PAGO | W1: EMPLEADO | X1: # AG ESSALUD | Y1: CODIGO EMPRESA
A2: EMPRESA | B2: CLARKE, MODET & CO. PERU S.A.C. | E2: R.U.C. | F2: 20256396000 | G2: MES | H2: =Detallado!R2 -> 05 | I2: AÑO | J2: =Detallado!S2 -> 2026 | K2: F. INGRESO | L2: =VLOOKUP(A6,'BD Total'!$A$2:$EZ$17,11,FALSE) -> 45637 | O2: # | P2: 1 | W2: 1007874085 | X2: 260130RRCOI9 | Y2: 07874085
E3: PERIODO | F3: =VLOOKUP($A$6,Detallado!$C:$U,16,FALSE) -> 05 | G3: DEL | H3: =VLOOKUP($A$6,Detallado!$C:$U,18,FALSE) -> 01/05/2026 | I3: AL | J3: =VLOOKUP($A$6,Detallado!$C:$U,19,FALSE) -> 46173 | K3: F. RETIRO | W3: 1040703418 | X3: 595200FCCCA8 | Y3: 40703418
W4: 1044771836 | X4: 621441RFSRR2 | Y4: 44771836
A5: CÓDIGO | B5: NOMBRES Y APELLIDOS | E5: CARGO | I5: AREA | W5: 1045191394 | X5: 322431AABAT4 | Y5: 45191394
A6: 42683912 | B6: =VLOOKUP(A6,Dev!$C$1:$D$78,2,FALSE) -> GUILLERMO HENRY HIRAOKA MARINA | E6: =VLOOKUP(A6,'BD Total'!$A$2:$EZ$18,77,FALSE) -> IP SPECIALIST | I6: =VLOOKUP(A6,'BD Total'!$A$2:$EZ$18,81,FALSE) -> TRADEMARKS | W6: 1046129072 | X6: 628890LLCAD9 | Y6: 46129072
A7: D.N.I. | B7: CUSPP AFP | C7: # AG ESSALUD | E7: SALARIO | G7: MONEDA | I7: CODIGO EMPRESA | K7: A.F.P. | W7: 1046722547 | X7: 632311FKROJ0 | Y7: 46722547
A8: =VLOOKUP(A6,'BD Total'!$A$2:$EZ$18,2,FALSE) -> 42683912 | B8: =VLOOKUP(A6,'BD Total'!$A$2:$EZ$18,85,FALSE) -> 309631GHMAI4 | C8: =VLOOKUP(A6,$W$1:$Y$20,2,FALSE) -> 309631GHMAI4 | E8: =VLOOKUP(A6,'BD Total'!$A$2:$EZ$18,22,FALSE) -> 5768 | G8: SOL | I8: =VLOOKUP(A6,$W$1:$Y$20,3,FALSE) -> 42683912 | K8: =VLOOKUP(A6,'BD Total'!$A$2:$EZ$18,101,FALSE) -> HABITAT | W8: 1047924040 | X8: 641640MNERI3 | Y8: 47924040
W9: 1070165336 | X9: 640621VFCNT9 | Y9: 70165336
A10: REMUNERACIONES | E10: DESCUENTOS TRABAJADOR | I10: APORTACIONES EMPLEADOR | W10: 1070680748 | X10: 0 | Y10: 70680748
A11: CONCEPTO | C11: HORAS | D11: VALOR | E11: CONCEPTO | G11: HORAS | H11: VALOR | I11: CONCEPTO | K11: HORAS | L11: VALOR | W11: 1072251509 | X11: 631390CHTMR2 | Y11: 72251509
A12: A000 SUELDO BASICO | C12: =SUMIF(Dev!$B:$B,CONCATENATE($A$6,A12),Dev!$L:$L) -> 240 | D12: =SUMIF(Dev!$B:$B,CONCATENATE($A$6,A12),Dev!M:M) -> 5768 | E12: I100 APORTE OBLIGATORIO AFP | G12: =SUMIF(Dev!$B:$B,CONCATENATE($A$6,E12),Dev!$L:$L) -> 0 | H12: =SUMIF(Dev!$B:$B,CONCATENATE($A$6,E12),Dev!N:N) -> 576.8 | I12: APORTE A ESSALUD | K12: 0 | L12: =VLOOKUP(A6,ESSALUD!$B$1:$G$19,6,FALSE) -> 389.34 | W12: 1077485287 | X12: 655610ZCBIT4 | Y12: 77485287
A13: D013 AUXILIO DE MOVILIDAD | C13: =SUMIF(Dev!$B:$B,CONCATENATE($A$6,A13),Dev!$L:$L) -> 0 | D13: =SUMIF(Dev!$B:$B,CONCATENATE($A$6,A13),Dev!M:M) -> 48 | E13: I200 SOBREVIVENCIA AFP | G13: =SUMIF(Dev!$B:$B,CONCATENATE($A$6,E13),Dev!$L:$L) -> 0 | H13: =SUMIF(Dev!$B:$B,CONCATENATE($A$6,E13),Dev!N:N) -> 79.02 | I13: CREDITO EPS | K13: 0 | L13: =VLOOKUP(A6,ESSALUD!$B$1:$H$19,7,FALSE) -> 129.78 | W13: 2001252358 | X13: 627991JMXQX0 | Y13: 001252358
E14: R000 RETENCION IMPUESTO A LA RENTA | G14: =SUMIF(Dev!$B:$B,CONCATENATE($A$6,E14),Dev!$L:$L) -> 0 | H14: =SUMIF(Dev!$B:$B,CONCATENATE($A$6,E14),Dev!N:N) -> 368.65 | W14: 42115329 | X14: FACILITIES | Y14: 42115329
W15: 42683912 | X15: 309631GHMAI4 | Y15: 42683912
W16: 72836862 | X16: 663680JMDIO1 | Y16: 72836862
W17: 76607245 | X17: N/A | Y17: 76607245
W18: 74026184 | X18: N/A | Y18: 74026184
I25: TOTAL APORTE EMPLEADOR | L25: =SUM(L12:L24) -> 519.12
A26: REMUNERACION TOTAL | D26: =SUM(D12:D24) -> 5816 | E26: DESCUENTOS TOTALES | H26: =SUM(H12:H24) -> 1024.47 | I26: REMUNERACION NETA | L26: =+D26-H26 -> 4791.53
F36: REPRESENTANTE LEGAL | J36: RECIBI CONFORME TRABAJADOR

Sheet PS1 (13)
A1: BOLETA DE PAGO | W1: EMPLEADO | X1: # AG ESSALUD | Y1: CODIGO EMPRESA
A2: EMPRESA | B2: CLARKE, MODET & CO. PERU S.A.C. | E2: R.U.C. | F2: 20256396000 | G2: MES | H2: =Detallado!R2 -> 05 | I2: AÑO | J2: =Detallado!S2 -> 2026 | K2: F. INGRESO | L2: =VLOOKUP(A6,'BD Total'!$A$2:$EZ$17,11,FALSE) -> 45740 | O2: # | P2: 1 | W2: 1007874085 | X2: 260130RRCOI9 | Y2: 07874085
E3: PERIODO | F3: =VLOOKUP($A$6,Detallado!$C:$U,16,FALSE) -> 05 | G3: DEL | H3: =VLOOKUP($A$6,Detallado!$C:$U,18,FALSE) -> 01/05/2026 | I3: AL | J3: =VLOOKUP($A$6,Detallado!$C:$U,19,FALSE) -> 46173 | K3: F. RETIRO | W3: 1040703418 | X3: 595200FCCCA8 | Y3: 40703418
W4: 1044771836 | X4: 621441RFSRR2 | Y4: 44771836
A5: CÓDIGO | B5: NOMBRES Y APELLIDOS | E5: CARGO | I5: AREA | W5: 1045191394 | X5: 322431AABAT4 | Y5: 45191394
A6: 42115329 | B6: =VLOOKUP(A6,Dev!$C$1:$D$78,2,FALSE) -> SARA MILAGROS SOTO LLOCLLA | E6: =VLOOKUP(A6,'BD Total'!$A$2:$EZ$18,77,FALSE) -> IP PROSECUTION SPECIALIST | I6: =VLOOKUP(A6,'BD Total'!$A$2:$EZ$18,81,FALSE) -> CENTRAL SERVICES | W6: 1046129072 | X6: 628890LLCAD9 | Y6: 46129072
A7: D.N.I. | B7: CUSPP AFP | C7: # AG ESSALUD | E7: SALARIO | G7: MONEDA | I7: CODIGO EMPRESA | K7: A.F.P. | W7: 1046722547 | X7: 632311FKROJ0 | Y7: 46722547
A8: =VLOOKUP(A6,'BD Total'!$A$2:$EZ$18,2,FALSE) -> 42115329 | B8: =VLOOKUP(A6,'BD Total'!$A$2:$EZ$18,85,FALSE) -> FACILITIES | C8: =VLOOKUP(A6,$W$1:$Y$20,2,FALSE) -> FACILITIES | E8: =VLOOKUP(A6,'BD Total'!$A$2:$EZ$18,22,FALSE) -> 3090 | G8: SOL | I8: =VLOOKUP(A6,$W$1:$Y$20,3,FALSE) -> 42115329 | K8: =VLOOKUP(A6,'BD Total'!$A$2:$EZ$18,101,FALSE) -> INTEGRA | W8: 1047924040 | X8: 641640MNERI3 | Y8: 47924040
W9: 1070165336 | X9: 640621VFCNT9 | Y9: 70165336
A10: REMUNERACIONES | E10: DESCUENTOS TRABAJADOR | I10: APORTACIONES EMPLEADOR | W10: 1070680748 | X10: 0 | Y10: 70680748
A11: CONCEPTO | C11: HORAS | D11: VALOR | E11: CONCEPTO | G11: HORAS | H11: VALOR | I11: CONCEPTO | K11: HORAS | L11: VALOR | W11: 1072251509 | X11: 631390CHTMR2 | Y11: 72251509
A12: A000 SUELDO BASICO | C12: =SUMIF(Dev!$B:$B,CONCATENATE($A$6,A12),Dev!$L:$L) -> 240 | D12: =SUMIF(Dev!$B:$B,CONCATENATE($A$6,A12),Dev!M:M) -> 3090 | E12: I100 APORTE OBLIGATORIO AFP | G12: =SUMIF(Dev!$B:$B,CONCATENATE($A$6,E12),Dev!$L:$L) -> 0 | H12: =SUMIF(Dev!$B:$B,CONCATENATE($A$6,E12),Dev!N:N) -> 309 | I12: APORTE A ESSALUD | K12: 0 | L12: =VLOOKUP(A6,ESSALUD!$B$1:$G$19,6,FALSE) -> 208.575 | W12: 1077485287 | X12: 655610ZCBIT4 | Y12: 77485287
A13: D013 AUXILIO DE MOVILIDAD | C13: =SUMIF(Dev!$B:$B,CONCATENATE($A$6,A13),Dev!$L:$L) -> 0 | D13: =SUMIF(Dev!$B:$B,CONCATENATE($A$6,A13),Dev!M:M) -> 36 | E13: I200 SOBREVIVENCIA AFP | G13: =SUMIF(Dev!$B:$B,CONCATENATE($A$6,E13),Dev!$L:$L) -> 0 | H13: =SUMIF(Dev!$B:$B,CONCATENATE($A$6,E13),Dev!N:N) -> 42.33 | I13: CREDITO EPS | K13: 0 | L13: =VLOOKUP(A6,ESSALUD!$B$1:$H$19,7,FALSE) -> 69.525 | W13: 2001252358 | X13: 627991JMXQX0 | Y13: 001252358
E14: I300 COMISION VARIABLE AFP | G14: =SUMIF(Dev!$B:$B,CONCATENATE($A$6,E14),Dev!$L:$L) -> 0 | H14: =SUMIF(Dev!$B:$B,CONCATENATE($A$6,E14),Dev!N:N) -> 47.9 | W14: 42115329 | X14: FACILITIES | Y14: 42115329
E15: R000 RETENCION IMPUESTO A LA RENTA | G15: =SUMIF(Dev!$B:$B,CONCATENATE($A$6,E15),Dev!$L:$L) -> 0 | H15: =SUMIF(Dev!$B:$B,CONCATENATE($A$6,E15),Dev!N:N) -> 36.25 | W15: 42683912 | X15: 309631GHMAI4 | Y15: 42683912
W16: 72836862 | X16: 663680JMDIO1 | Y16: 72836862
W17: 76607245 | X17: N/A | Y17: 76607245
W18: 74026184 | X18: N/A | Y18: 74026184
I25: TOTAL APORTE EMPLEADOR | L25: =SUM(L12:L24) -> 278.1
A26: REMUNERACION TOTAL | D26: =SUM(D12:D24) -> 3126 | E26: DESCUENTOS TOTALES | H26: =SUM(H12:H24) -> 435.48 | I26: REMUNERACION NETA | L26: =+D26-H26 -> 2690.52
F36: REPRESENTANTE LEGAL | J36: RECIBI CONFORME TRABAJADOR

Sheet PS1 (12)
A1: BOLETA DE PAGO | W1: EMPLEADO | X1: # AG ESSALUD | Y1: CODIGO EMPRESA
A2: EMPRESA | B2: CLARKE, MODET & CO. PERU S.A.C. | E2: R.U.C. | F2: 20256396000 | G2: MES | H2: =Detallado!R2 -> 05 | I2: AÑO | J2: =Detallado!S2 -> 2026 | K2: F. INGRESO | L2: =VLOOKUP(A6,'BD Total'!$A$2:$EZ$17,11,FALSE) -> 42438 | O2: # | P2: 1 | W2: 1007874085 | X2: 260130RRCOI9 | Y2: 07874085
E3: PERIODO | F3: =VLOOKUP($A$6,Detallado!$C:$U,16,FALSE) -> 05 | G3: DEL | H3: =VLOOKUP($A$6,Detallado!$C:$U,18,FALSE) -> 01/05/2026 | I3: AL | J3: =VLOOKUP($A$6,Detallado!$C:$U,19,FALSE) -> 46173 | K3: F. RETIRO | W3: 1040703418 | X3: 595200FCCCA8 | Y3: 40703418
W4: 1044771836 | X4: 621441RFSRR2 | Y4: 44771836
A5: CÓDIGO | B5: NOMBRES Y APELLIDOS | E5: CARGO | I5: AREA | W5: 1045191394 | X5: 322431AABAT4 | Y5: 45191394
A6: 2001252358 | B6: =VLOOKUP(A6,Dev!$C$1:$D$78,2,FALSE) -> JOSE NORBERT MARQUIS XXX | E6: =VLOOKUP(A6,'BD Total'!$A$2:$EZ$18,77,FALSE) -> IP SPECIALIST | I6: =VLOOKUP(A6,'BD Total'!$A$2:$EZ$18,81,FALSE) -> INVENTIONS | W6: 1046129072 | X6: 628890LLCAD9 | Y6: 46129072
A7: D.N.I. | B7: CUSPP AFP | C7: # AG ESSALUD | E7: SALARIO | G7: MONEDA | I7: CODIGO EMPRESA | K7: A.F.P. | W7: 1046722547 | X7: 632311FKROJ0 | Y7: 46722547
A8: =VLOOKUP(A6,'BD Total'!$A$2:$EZ$18,2,FALSE) -> 001252358 | B8: =VLOOKUP(A6,'BD Total'!$A$2:$EZ$18,85,FALSE) -> 627991JMXQX0 | C8: =VLOOKUP(A6,$W$1:$Y$20,2,FALSE) -> 627991JMXQX0 | E8: =VLOOKUP(A6,'BD Total'!$A$2:$EZ$18,22,FALSE) -> 6644 | G8: SOL | I8: =VLOOKUP(A6,$W$1:$Y$20,3,FALSE) -> 001252358 | K8: =VLOOKUP(A6,'BD Total'!$A$2:$EZ$18,101,FALSE) -> HABITAT | W8: 1047924040 | X8: 641640MNERI3 | Y8: 47924040
W9: 1070165336 | X9: 640621VFCNT9 | Y9: 70165336
A10: REMUNERACIONES | E10: DESCUENTOS TRABAJADOR | I10: APORTACIONES EMPLEADOR | W10: 1070680748 | X10: 0 | Y10: 70680748
A11: CONCEPTO | C11: HORAS | D11: VALOR | E11: CONCEPTO | G11: HORAS | H11: VALOR | I11: CONCEPTO | K11: HORAS | L11: VALOR | W11: 1072251509 | X11: 631390CHTMR2 | Y11: 72251509
A12: A000 SUELDO BASICO | C12: =SUMIF(Dev!$B:$B,CONCATENATE($A$6,A12),Dev!$L:$L) -> 240 | D12: =SUMIF(Dev!$B:$B,CONCATENATE($A$6,A12),Dev!M:M) -> 6644 | E12: I100 APORTE OBLIGATORIO AFP | G12: =SUMIF(Dev!$B:$B,CONCATENATE($A$6,E12),Dev!$L:$L) -> 0 | H12: =SUMIF(Dev!$B:$B,CONCATENATE($A$6,E12),Dev!N:N) -> 664.4 | I12: APORTE A ESSALUD | K12: 0 | L12: =VLOOKUP(A6,ESSALUD!$B$1:$G$19,6,FALSE) -> 448.47 | W12: 1077485287 | X12: 655610ZCBIT4 | Y12: 77485287
A13: D013 AUXILIO DE MOVILIDAD | C13: =SUMIF(Dev!$B:$B,CONCATENATE($A$6,A13),Dev!$L:$L) -> 0 | D13: =SUMIF(Dev!$B:$B,CONCATENATE($A$6,A13),Dev!M:M) -> 48 | E13: I200 SOBREVIVENCIA AFP | G13: =SUMIF(Dev!$B:$B,CONCATENATE($A$6,E13),Dev!$L:$L) -> 0 | H13: =SUMIF(Dev!$B:$B,CONCATENATE($A$6,E13),Dev!N:N) -> 91.02 | I13: CREDITO EPS | K13: 0 | L13: =VLOOKUP(A6,ESSALUD!$B$1:$H$19,7,FALSE) -> 149.49 | W13: 2001252358 | X13: 627991JMXQX0 | Y13: 001252358
E14: R000 RETENCION IMPUESTO A LA RENTA | G14: =SUMIF(Dev!$B:$B,CONCATENATE($A$6,#REF!),Dev!$L:$L) -> 0 | H14: =SUMIF(Dev!$B:$B,CONCATENATE($A$6,E14),Dev!N:N) -> 513.58 | W14: 42115329 | X14: FACILITIES | Y14: 42115329
W15: 42683912 | X15: 309631GHMAI4 | Y15: 42683912
W16: 72836862 | X16: 663680JMDIO1 | Y16: 72836862
W17: 76607245 | X17: N/A | Y17: 76607245
W18: 74026184 | X18: N/A | Y18: 74026184
I25: TOTAL APORTE EMPLEADOR | L25: =SUM(L12:L24) -> 597.96
A26: REMUNERACION TOTAL | D26: =SUM(D12:D24) -> 6692 | E26: DESCUENTOS TOTALES | H26: =SUM(H12:H24) -> 1269 | I26: REMUNERACION NETA | L26: =+D26-H26 -> 5423
F36: REPRESENTANTE LEGAL | J36: RECIBI CONFORME TRABAJADOR

Sheet PS1 (11)
A1: BOLETA DE PAGO | W1: EMPLEADO | X1: # AG ESSALUD | Y1: CODIGO EMPRESA
A2: EMPRESA | B2: CLARKE, MODET & CO. PERU S.A.C. | E2: R.U.C. | F2: 20256396000 | G2: MES | H2: =Detallado!R2 -> 05 | I2: AÑO | J2: =Detallado!S2 -> 2026 | K2: F. INGRESO | L2: =VLOOKUP(A6,'BD Total'!$A$2:$EZ$17,11,FALSE) -> 45323 | O2: # | P2: 1 | W2: 1007874085 | X2: 260130RRCOI9 | Y2: 07874085
E3: PERIODO | F3: =VLOOKUP($A$6,Detallado!$C:$U,16,FALSE) -> 05 | G3: DEL | H3: =VLOOKUP($A$6,Detallado!$C:$U,18,FALSE) -> 01/05/2026 | I3: AL | J3: =VLOOKUP($A$6,Detallado!$C:$U,19,FALSE) -> 46173 | K3: F. RETIRO | W3: 1040703418 | X3: 595200FCCCA8 | Y3: 40703418
W4: 1044771836 | X4: 621441RFSRR2 | Y4: 44771836
A5: CÓDIGO | B5: NOMBRES Y APELLIDOS | E5: CARGO | I5: AREA | W5: 1045191394 | X5: 322431AABAT4 | Y5: 45191394
A6: 1077485287 | B6: =VLOOKUP(A6,Dev!$C$1:$D$78,2,FALSE) -> ZULEMA BELINDA CADILLO BRITO | E6: =VLOOKUP(A6,'BD Total'!$A$2:$EZ$18,77,FALSE) -> IP PROSECUTION SPECIALIST | I6: =VLOOKUP(A6,'BD Total'!$A$2:$EZ$18,81,FALSE) -> CENTRAL SERVICES | W6: 1046129072 | X6: 628890LLCAD9 | Y6: 46129072
A7: D.N.I. | B7: CUSPP AFP | C7: # AG ESSALUD | E7: SALARIO | G7: MONEDA | I7: CODIGO EMPRESA | K7: A.F.P. | W7: 1046722547 | X7: 632311FKROJ0 | Y7: 46722547
A8: =VLOOKUP(A6,'BD Total'!$A$2:$EZ$18,2,FALSE) -> 77485287 | B8: =VLOOKUP(A6,'BD Total'!$A$2:$EZ$18,85,FALSE) -> 655610ZCBIT4 | C8: =VLOOKUP(A6,$W$1:$Y$20,2,FALSE) -> 655610ZCBIT4 | E8: =VLOOKUP(A6,'BD Total'!$A$2:$EZ$18,22,FALSE) -> 2142 | G8: SOL | I8: =VLOOKUP(A6,$W$1:$Y$20,3,FALSE) -> 77485287 | K8: =VLOOKUP(A6,'BD Total'!$A$2:$EZ$18,101,FALSE) -> PRIMA | W8: 1047924040 | X8: 641640MNERI3 | Y8: 47924040
W9: 1070165336 | X9: 640621VFCNT9 | Y9: 70165336
A10: REMUNERACIONES | E10: DESCUENTOS TRABAJADOR | I10: APORTACIONES EMPLEADOR | W10: 1070680748 | X10: 0 | Y10: 70680748
A11: CONCEPTO | C11: HORAS | D11: VALOR | E11: CONCEPTO | G11: HORAS | H11: VALOR | I11: CONCEPTO | K11: HORAS | L11: VALOR | W11: 1072251509 | X11: 631390CHTMR2 | Y11: 72251509
A12: A000 SUELDO BASICO | C12: =SUMIF(Dev!$B:$B,CONCATENATE($A$6,A12),Dev!$L:$L) -> 240 | D12: =SUMIF(Dev!$B:$B,CONCATENATE($A$6,A12),Dev!M:M) -> 2142 | E12: I100 APORTE OBLIGATORIO AFP | G12: =SUMIF(Dev!$B:$B,CONCATENATE($A$6,E12),Dev!$L:$L) -> 0 | H12: =SUMIF(Dev!$B:$B,CONCATENATE($A$6,E12),Dev!N:N) -> 214.2 | I12: APORTE A ESSALUD | K12: 0 | L12: =VLOOKUP(A6,ESSALUD!$B$1:$G$19,6,FALSE) -> 144.585 | W12: 1077485287 | X12: 655610ZCBIT4 | Y12: 77485287
A13: D013 AUXILIO DE MOVILIDAD | C13: =SUMIF(Dev!$B:$B,CONCATENATE($A$6,A13),Dev!$L:$L) -> 0 | D13: =SUMIF(Dev!$B:$B,CONCATENATE($A$6,A13),Dev!M:M) -> 48 | E13: I200 SOBREVIVENCIA AFP | G13: =SUMIF(Dev!$B:$B,CONCATENATE($A$6,E13),Dev!$L:$L) -> 0 | H13: =SUMIF(Dev!$B:$B,CONCATENATE($A$6,E13),Dev!N:N) -> 29.35 | I13: CREDITO EPS | K13: 0 | L13: =VLOOKUP(A6,ESSALUD!$B$1:$H$19,7,FALSE) -> 48.195 | W13: 2001252358 | X13: 627991JMXQX0 | Y13: 001252358
W14: 42115329 | X14: FACILITIES | Y14: 42115329
W15: 42683912 | X15: 309631GHMAI4 | Y15: 42683912
W16: 72836862 | X16: 663680JMDIO1 | Y16: 72836862
W17: 76607245 | X17: N/A | Y17: 76607245
W18: 74026184 | X18: N/A | Y18: 74026184
I25: TOTAL APORTE EMPLEADOR | L25: =SUM(L12:L24) -> 192.78
A26: REMUNERACION TOTAL | D26: =SUM(D12:D24) -> 2190 | E26: DESCUENTOS TOTALES | H26: =SUM(H12:H24) -> 243.55 | I26: REMUNERACION NETA | L26: =+D26-H26 -> 1946.45
F36: REPRESENTANTE LEGAL | J36: RECIBI CONFORME TRABAJADOR

Sheet PS1 (10)
A1: BOLETA DE PAGO | W1: EMPLEADO | X1: # AG ESSALUD | Y1: CODIGO EMPRESA
A2: EMPRESA | B2: CLARKE, MODET & CO. PERU S.A.C. | E2: R.U.C. | F2: 20256396000 | G2: MES | H2: =Detallado!R2 -> 05 | I2: AÑO | J2: =Detallado!S2 -> 2026 | K2: F. INGRESO | L2: =VLOOKUP(A6,'BD Total'!$A$2:$EZ$17,11,FALSE) -> 43241 | W2: 1007874085 | X2: 260130RRCOI9 | Y2: 07874085
E3: PERIODO | F3: =VLOOKUP($A$6,Detallado!$C:$U,16,FALSE) -> 05 | G3: DEL | H3: =VLOOKUP($A$6,Detallado!$C:$U,18,FALSE) -> 01/05/2026 | I3: AL | J3: =VLOOKUP($A$6,Detallado!$C:$U,19,FALSE) -> 46173 | K3: F. RETIRO | W3: 1040703418 | X3: 595200FCCCA8 | Y3: 40703418
W4: 1044771836 | X4: 621441RFSRR2 | Y4: 44771836
A5: CÓDIGO | B5: NOMBRES Y APELLIDOS | E5: CARGO | I5: AREA | W5: 1045191394 | X5: 322431AABAT4 | Y5: 45191394
A6: 1072251509 | B6: =VLOOKUP(A6,Dev!$C$1:$D$78,2,FALSE) -> CYNTHIA FIORELLA HUAMAN TORRES | E6: =VLOOKUP(A6,'BD Total'!$A$2:$EZ$18,77,FALSE) -> PATENT SPECIALIST | I6: =VLOOKUP(A6,'BD Total'!$A$2:$EZ$18,81,FALSE) -> INVENTIONS | W6: 1046129072 | X6: 628890LLCAD9 | Y6: 46129072
A7: D.N.I. | B7: CUSPP AFP | C7: # AG ESSALUD | E7: SALARIO | G7: MONEDA | I7: CODIGO EMPRESA | K7: A.F.P. | W7: 1046722547 | X7: 632311FKROJ0 | Y7: 46722547
A8: =VLOOKUP(A6,'BD Total'!$A$2:$EZ$18,2,FALSE) -> 72251509 | B8: =VLOOKUP(A6,'BD Total'!$A$2:$EZ$18,85,FALSE) -> 631390CHTMR2 | C8: =VLOOKUP(A6,$W$1:$Y$20,2,FALSE) -> 631390CHTMR2 | E8: =VLOOKUP(A6,'BD Total'!$A$2:$EZ$18,22,FALSE) -> 4631 | G8: SOL | I8: =VLOOKUP(A6,$W$1:$Y$20,3,FALSE) -> 72251509 | K8: =VLOOKUP(A6,'BD Total'!$A$2:$EZ$18,101,FALSE) -> HABITAT | W8: 1047924040 | X8: 641640MNERI3 | Y8: 47924040
W9: 1070165336 | X9: 640621VFCNT9 | Y9: 70165336
A10: REMUNERACIONES | E10: DESCUENTOS TRABAJADOR | I10: APORTACIONES EMPLEADOR | W10: 1070680748 | X10: 0 | Y10: 70680748
A11: CONCEPTO | C11: HORAS | D11: VALOR | E11: CONCEPTO | G11: HORAS | H11: VALOR | I11: CONCEPTO | K11: HORAS | L11: VALOR | W11: 1072251509 | X11: 631390CHTMR2 | Y11: 72251509
A12: A000 SUELDO BASICO | C12: =SUMIF(Dev!$B:$B,CONCATENATE($A$6,A12),Dev!$L:$L) -> 168 | D12: =SUMIF(Dev!$B:$B,CONCATENATE($A$6,A12),Dev!M:M) -> 3241.7 | E12: I100 APORTE OBLIGATORIO AFP | G12: =SUMIF(Dev!$B:$B,CONCATENATE($A$6,E12),Dev!$L:$L) -> 0 | H12: =SUMIF(Dev!$B:$B,CONCATENATE($A$6,E12),Dev!N:N) -> 474.4 | I12: APORTE A ESSALUD | K12: 0 | L12: =VLOOKUP(A6,ESSALUD!$B$1:$G$19,6,FALSE) -> 426.96 | W12: 1077485287 | X12: 655610ZCBIT4 | Y12: 77485287
A13: D013 AUXILIO DE MOVILIDAD | C13: =SUMIF(Dev!$B:$B,CONCATENATE($A$6,A13),Dev!$L:$L) -> 0 | D13: =SUMIF(Dev!$B:$B,CONCATENATE($A$6,A13),Dev!M:M) -> 32 | E13: I200 SOBREVIVENCIA AFP | G13: =SUMIF(Dev!$B:$B,CONCATENATE($A$6,E13),Dev!$L:$L) -> 0 | H13: =SUMIF(Dev!$B:$B,CONCATENATE($A$6,E13),Dev!N:N) -> 64.99 | W13: 2001252358 | X13: 627991JMXQX0 | Y13: 001252358
A14: G006 VACACIONES | C14: =SUMIF(Dev!$B:$B,CONCATENATE($A$6,A14),Dev!$L:$L) -> 72 | D14: =SUMIF(Dev!$B:$B,CONCATENATE($A$6,A14),Dev!M:M) -> 1389.3 | E14: R000 RETENCION IMPUESTO A LA RENTA | G14: =SUMIF(Dev!$B:$B,CONCATENATE($A$6,#REF!),Dev!$L:$L) -> 0 | H14: =SUMIF(Dev!$B:$B,CONCATENATE($A$6,E14),Dev!N:N) -> 197.7 | W14: 42115329 | X14: FACILITIES | Y14: 42115329
A15: A012 ASIGNACION FAMILIAR | C15: =SUMIF(Dev!$B:$B,CONCATENATE($A$6,A15),Dev!$L:$L) -> 0 | D15: =SUMIF(Dev!$B:$B,CONCATENATE($A$6,A15),Dev!M:M) -> 113 | W15: 42683912 | X15: 309631GHMAI4 | Y15: 42683912
W16: 72836862 | X16: 663680JMDIO1 | Y16: 72836862
W17: 76607245 | X17: N/A | Y17: 76607245
W18: 74026184 | X18: N/A | Y18: 74026184
I25: TOTAL APORTE EMPLEADOR | L25: =SUM(L12:L24) -> 426.96
A26: REMUNERACION TOTAL | D26: =SUM(D12:D24) -> 4776 | E26: DESCUENTOS TOTALES | H26: =SUM(H12:H24) -> 737.09 | I26: REMUNERACION NETA | L26: =+D26-H26 -> 4038.91
F36: REPRESENTANTE LEGAL | J36: RECIBI CONFORME TRABAJADOR

Sheet PS1 (9)
A1: BOLETA DE PAGO | W1: EMPLEADO | X1: # AG ESSALUD | Y1: CODIGO EMPRESA
A2: EMPRESA | B2: CLARKE, MODET & CO. PERU S.A.C. | E2: R.U.C. | F2: 20256396000 | G2: MES | H2: =Detallado!R2 -> 05 | I2: AÑO | J2: =Detallado!S2 -> 2026 | K2: F. INGRESO | L2: =VLOOKUP(A6,'BD Total'!$A$2:$EZ$17,11,FALSE) -> 44879 | O2: # | P2: 1 | W2: 1007874085 | X2: 260130RRCOI9 | Y2: 07874085
E3: PERIODO | F3: =VLOOKUP($A$6,Detallado!$C:$U,16,FALSE) -> 05 | G3: DEL | H3: =VLOOKUP($A$6,Detallado!$C:$U,18,FALSE) -> 01/05/2026 | I3: AL | J3: =VLOOKUP($A$6,Detallado!$C:$U,19,FALSE) -> 46173 | K3: F. RETIRO | W3: 1040703418 | X3: 595200FCCCA8 | Y3: 40703418
W4: 1044771836 | X4: 621441RFSRR2 | Y4: 44771836
A5: CÓDIGO | B5: NOMBRES Y APELLIDOS | E5: CARGO | I5: AREA | W5: 1045191394 | X5: 322431AABAT4 | Y5: 45191394
A6: 1070680748 | B6: =VLOOKUP(A6,Dev!$C$1:$D$78,2,FALSE) -> LIZ VALERIA SOLANO CARRILLO | E6: =VLOOKUP(A6,'BD Total'!$A$2:$EZ$18,77,FALSE) -> IP SPECIALIST | I6: =VLOOKUP(A6,'BD Total'!$A$2:$EZ$18,81,FALSE) -> TRADEMARKS | W6: 1046129072 | X6: 628890LLCAD9 | Y6: 46129072
A7: D.N.I. | B7: CUSPP AFP | C7: # AG ESSALUD | E7: SALARIO | G7: MONEDA | I7: CODIGO EMPRESA | K7: A.F.P. | W7: 1046722547 | X7: 632311FKROJ0 | Y7: 46722547
A8: =VLOOKUP(A6,'BD Total'!$A$2:$EZ$18,2,FALSE) -> 70680748 | B8: =VLOOKUP(A6,'BD Total'!$A$2:$EZ$18,85,FALSE) -> 0 | C8: =VLOOKUP(A6,$W$1:$Y$20,2,FALSE) -> 0 | E8: =VLOOKUP(A6,'BD Total'!$A$2:$EZ$18,22,FALSE) -> 6125 | G8: SOL | I8: =VLOOKUP(A6,$W$1:$Y$20,3,FALSE) -> 70680748 | K8: =VLOOKUP(A6,'BD Total'!$A$2:$EZ$18,101,FALSE) -> ONP | W8: 1047924040 | X8: 641640MNERI3 | Y8: 47924040
W9: 1070165336 | X9: 640621VFCNT9 | Y9: 70165336
A10: REMUNERACIONES | E10: DESCUENTOS TRABAJADOR | I10: APORTACIONES EMPLEADOR | W10: 1070680748 | X10: 0 | Y10: 70680748
A11: CONCEPTO | C11: HORAS | D11: VALOR | E11: CONCEPTO | G11: HORAS | H11: VALOR | I11: CONCEPTO | K11: HORAS | L11: VALOR | W11: 1072251509 | X11: 631390CHTMR2 | Y11: 72251509
A12: A000 SUELDO BASICO | C12: =SUMIF(Dev!$B:$B,CONCATENATE($A$6,A12),Dev!$L:$L) -> 152 | D12: =SUMIF(Dev!$B:$B,CONCATENATE($A$6,A12),Dev!M:M) -> 3879.17 | E12: I100 APORTE OBLIGATORIO AFP | G12: =SUMIF(Dev!$B:$B,CONCATENATE($A$6,E12),Dev!$L:$L) -> 0 | H12: =SUMIF(Dev!$B:$B,CONCATENATE($A$6,E12),Dev!N:N) -> 810.94 | I12: APORTE A ESSALUD | K12: 0 | L12: =VLOOKUP(A6,ESSALUD!$B$1:$G$19,6,FALSE) -> 421.065 | W12: 1077485287 | X12: 655610ZCBIT4 | Y12: 77485287
A13: A012 ASIGNACION FAMILIAR | C13: =SUMIF(Dev!$B:$B,CONCATENATE($A$6,A13),Dev!$L:$L) -> 0 | D13: =SUMIF(Dev!$B:$B,CONCATENATE($A$6,A13),Dev!M:M) -> 113 | E13: R000 RETENCION IMPUESTO A LA RENTA | G13: =SUMIF(Dev!$B:$B,CONCATENATE($A$6,#REF!),Dev!$L:$L) -> 0 | H13: =SUMIF(Dev!$B:$B,CONCATENATE($A$6,E13),Dev!N:N) -> 440.35 | I13: CREDITO EPS | K13: 0 | L13: =VLOOKUP(A6,ESSALUD!$B$1:$H$19,7,FALSE) -> 140.355 | W13: 2001252358 | X13: 627991JMXQX0 | Y13: 001252358
A14: G006 VACACIONES | C14: =SUMIF(Dev!$B:$B,CONCATENATE($A$6,A14),Dev!$L:$L) -> 88 | D14: =SUMIF(Dev!$B:$B,CONCATENATE($A$6,A14),Dev!M:M) -> 2245.83 | W14: 42115329 | X14: FACILITIES | Y14: 42115329
W15: 42683912 | X15: 309631GHMAI4 | Y15: 42683912
W16: 72836862 | X16: 663680JMDIO1 | Y16: 72836862
W17: 76607245 | X17: N/A | Y17: 76607245
W18: 74026184 | X18: N/A | Y18: 74026184
I25: TOTAL APORTE EMPLEADOR | L25: =SUM(L12:L24) -> 561.42
A26: REMUNERACION TOTAL | D26: =SUM(D12:D24) -> 6238 | E26: DESCUENTOS TOTALES | H26: =SUM(H12:H24) -> 1251.29 | I26: REMUNERACION NETA | L26: =+D26-H26 -> 4986.71
F36: REPRESENTANTE LEGAL | J36: RECIBI CONFORME TRABAJADOR

Sheet PS1 (8)
A1: BOLETA DE PAGO | W1: EMPLEADO | X1: # AG ESSALUD | Y1: CODIGO EMPRESA
A2: EMPRESA | B2: CLARKE, MODET & CO. PERU S.A.C. | E2: R.U.C. | F2: 20256396000 | G2: MES | H2: =Detallado!R2 -> 05 | I2: AÑO | J2: =Detallado!S2 -> 2026 | K2: F. INGRESO | L2: =VLOOKUP(A6,'BD Total'!$A$2:$EZ$17,11,FALSE) -> 44623 | O2: # | P2: 1 | W2: 1007874085 | X2: 260130RRCOI9 | Y2: 07874085
E3: PERIODO | F3: =VLOOKUP($A$6,Detallado!$C:$U,16,FALSE) -> 05 | G3: DEL | H3: =VLOOKUP($A$6,Detallado!$C:$U,18,FALSE) -> 01/05/2026 | I3: AL | J3: =VLOOKUP($A$6,Detallado!$C:$U,19,FALSE) -> 46173 | K3: F. RETIRO | W3: 1040703418 | X3: 595200FCCCA8 | Y3: 40703418
W4: 1044771836 | X4: 621441RFSRR2 | Y4: 44771836
A5: CÓDIGO | B5: NOMBRES Y APELLIDOS | E5: CARGO | I5: AREA | W5: 1045191394 | X5: 322431AABAT4 | Y5: 45191394
A6: 1070165336 | B6: =VLOOKUP(A6,Dev!$C$1:$D$78,2,FALSE) -> VICTOR DANIEL FERNANDEZ CASTILLO | E6: =VLOOKUP(A6,'BD Total'!$A$2:$EZ$18,77,FALSE) -> PATENT SPECIALIST | I6: =VLOOKUP(A6,'BD Total'!$A$2:$EZ$18,81,FALSE) -> INVENTIONS | W6: 1046129072 | X6: 628890LLCAD9 | Y6: 46129072
A7: D.N.I. | B7: CUSPP AFP | C7: # AG ESSALUD | E7: SALARIO | G7: MONEDA | I7: CODIGO EMPRESA | K7: A.F.P. | W7: 1046722547 | X7: 632311FKROJ0 | Y7: 46722547
A8: =VLOOKUP(A6,'BD Total'!$A$2:$EZ$18,2,FALSE) -> 70165336 | B8: =VLOOKUP(A6,'BD Total'!$A$2:$EZ$18,85,FALSE) -> 640621VFCNT9 | C8: =VLOOKUP(A6,$W$1:$Y$20,2,FALSE) -> 640621VFCNT9 | E8: =VLOOKUP(A6,'BD Total'!$A$2:$EZ$18,22,FALSE) -> 4099 | G8: SOL | I8: =VLOOKUP(A6,$W$1:$Y$20,3,FALSE) -> 70165336 | K8: =VLOOKUP(A6,'BD Total'!$A$2:$EZ$18,101,FALSE) -> HABITAT | W8: 1047924040 | X8: 641640MNERI3 | Y8: 47924040
W9: 1070165336 | X9: 640621VFCNT9 | Y9: 70165336
A10: REMUNERACIONES | E10: DESCUENTOS TRABAJADOR | I10: APORTACIONES EMPLEADOR | W10: 1070680748 | X10: 0 | Y10: 70680748
A11: CONCEPTO | C11: HORAS | D11: VALOR | E11: CONCEPTO | G11: HORAS | H11: VALOR | I11: CONCEPTO | K11: HORAS | L11: VALOR | W11: 1072251509 | X11: 631390CHTMR2 | Y11: 72251509
A12: A000 SUELDO BASICO | C12: =SUMIF(Dev!$B:$B,CONCATENATE($A$6,A12),Dev!$L:$L) -> 184 | D12: =SUMIF(Dev!$B:$B,CONCATENATE($A$6,A12),Dev!M:M) -> 3142.57 | E12: I100 APORTE OBLIGATORIO AFP | G12: =SUMIF(Dev!$B:$B,CONCATENATE($A$6,E12),Dev!$L:$L) -> 0 | H12: =SUMIF(Dev!$B:$B,CONCATENATE($A$6,E12),Dev!N:N) -> 409.9 | I12: APORTE A ESSALUD | K12: 0 | L12: =VLOOKUP(A6,ESSALUD!$B$1:$G$19,6,FALSE) -> 276.6825 | W12: 1077485287 | X12: 655610ZCBIT4 | Y12: 77485287
A13: D013 AUXILIO DE MOVILIDAD | C13: =SUMIF(Dev!$B:$B,CONCATENATE($A$6,A13),Dev!$L:$L) -> 0 | D13: =SUMIF(Dev!$B:$B,CONCATENATE($A$6,A13),Dev!M:M) -> 36 | E13: I200 SOBREVIVENCIA AFP | G13: =SUMIF(Dev!$B:$B,CONCATENATE($A$6,E13),Dev!$L:$L) -> 0 | H13: =SUMIF(Dev!$B:$B,CONCATENATE($A$6,E13),Dev!N:N) -> 56.16 | I13: CREDITO EPS | K13: 0 | L13: =VLOOKUP(A6,ESSALUD!$B$1:$H$19,7,FALSE) -> 92.2275 | W13: 2001252358 | X13: 627991JMXQX0 | Y13: 001252358
A14: G006 VACACIONES | C14: =SUMIF(Dev!$B:$B,CONCATENATE($A$6,A14),Dev!$L:$L) -> 56 | D14: =SUMIF(Dev!$B:$B,CONCATENATE($A$6,A14),Dev!M:M) -> 956.43 | E14: R000 RETENCION IMPUESTO A LA RENTA | G14: =SUMIF(Dev!$B:$B,CONCATENATE($A$6,#REF!),Dev!$L:$L) -> 0 | H14: =SUMIF(Dev!$B:$B,CONCATENATE($A$6,E14),Dev!N:N) -> 131.63 | W14: 42115329 | X14: FACILITIES | Y14: 42115329
W15: 42683912 | X15: 309631GHMAI4 | Y15: 42683912
W16: 72836862 | X16: 663680JMDIO1 | Y16: 72836862
W17: 76607245 | X17: N/A | Y17: 76607245
W18: 74026184 | X18: N/A | Y18: 74026184
I25: TOTAL APORTE EMPLEADOR | L25: =SUM(L12:L24) -> 368.91
A26: REMUNERACION TOTAL | D26: =SUM(D12:D24) -> 4135 | E26: DESCUENTOS TOTALES | H26: =SUM(H12:H24) -> 597.69 | I26: REMUNERACION NETA | L26: =+D26-H26 -> 3537.31
F36: REPRESENTANTE LEGAL | J36: RECIBI CONFORME TRABAJADOR

Sheet PS1 (7)
A1: BOLETA DE PAGO | W1: EMPLEADO | X1: # AG ESSALUD | Y1: CODIGO EMPRESA
A2: EMPRESA | B2: CLARKE, MODET & CO. PERU S.A.C. | E2: R.U.C. | F2: 20256396000 | G2: MES | H2: =Detallado!R2 -> 05 | I2: AÑO | J2: =Detallado!S2 -> 2026 | K2: F. INGRESO | L2: =VLOOKUP(A6,'BD Total'!$A$2:$EZ$17,11,FALSE) -> 42632 | O2: # | P2: 1 | W2: 1007874085 | X2: 260130RRCOI9 | Y2: 07874085
E3: PERIODO | F3: =VLOOKUP($A$6,Detallado!$C:$U,16,FALSE) -> 05 | G3: DEL | H3: =VLOOKUP($A$6,Detallado!$C:$U,18,FALSE) -> 01/05/2026 | I3: AL | J3: =VLOOKUP($A$6,Detallado!$C:$U,19,FALSE) -> 46173 | K3: F. RETIRO | W3: 1040703418 | X3: 595200FCCCA8 | Y3: 40703418
W4: 1044771836 | X4: 621441RFSRR2 | Y4: 44771836
A5: CÓDIGO | B5: NOMBRES Y APELLIDOS | E5: CARGO | I5: AREA | W5: 1045191394 | X5: 322431AABAT4 | Y5: 45191394
A6: 1047924040 | B6: =VLOOKUP(A6,Dev!$C$1:$D$78,2,FALSE) -> MARÍA DEL CARMEN NEYRA ELLIOT | E6: =VLOOKUP(A6,'BD Total'!$A$2:$EZ$18,77,FALSE) -> QUALITY PROCESS MANAGER | I6: =VLOOKUP(A6,'BD Total'!$A$2:$EZ$18,81,FALSE) -> OPERATIONS | W6: 1046129072 | X6: 628890LLCAD9 | Y6: 46129072
A7: D.N.I. | B7: CUSPP AFP | C7: # AG ESSALUD | E7: SALARIO | G7: MONEDA | I7: CODIGO EMPRESA | K7: A.F.P. | W7: 1046722547 | X7: 632311FKROJ0 | Y7: 46722547
A8: =VLOOKUP(A6,'BD Total'!$A$2:$EZ$18,2,FALSE) -> 47924040 | B8: =VLOOKUP(A6,'BD Total'!$A$2:$EZ$18,85,FALSE) -> 641640MNERI3 | C8: =VLOOKUP(A6,$W$1:$Y$20,2,FALSE) -> 641640MNERI3 | E8: =VLOOKUP(A6,'BD Total'!$A$2:$EZ$18,22,FALSE) -> 6552 | G8: SOL | I8: =VLOOKUP(A6,$W$1:$Y$20,3,FALSE) -> 47924040 | K8: =VLOOKUP(A6,'BD Total'!$A$2:$EZ$18,101,FALSE) -> HABITAT | W8: 1047924040 | X8: 641640MNERI3 | Y8: 47924040
W9: 1070165336 | X9: 640621VFCNT9 | Y9: 70165336
A10: REMUNERACIONES | E10: DESCUENTOS TRABAJADOR | I10: APORTACIONES EMPLEADOR | W10: 1070680748 | X10: 0 | Y10: 70680748
A11: CONCEPTO | C11: HORAS | D11: VALOR | E11: CONCEPTO | G11: HORAS | H11: VALOR | I11: CONCEPTO | K11: HORAS | L11: VALOR | W11: 1072251509 | X11: 631390CHTMR2 | Y11: 72251509
A12: A000 SUELDO BASICO | C12: =SUMIF(Dev!$B:$B,CONCATENATE($A$6,A12),Dev!$L:$L) -> 144 | D12: =SUMIF(Dev!$B:$B,CONCATENATE($A$6,A12),Dev!M:M) -> 3931.2 | E12: I100 APORTE OBLIGATORIO AFP | G12: =SUMIF(Dev!$B:$B,CONCATENATE($A$6,E12),Dev!$L:$L) -> 0 | H12: =SUMIF(Dev!$B:$B,CONCATENATE($A$6,E12),Dev!N:N) -> 655.2 | I12: APORTE A ESSALUD | K12: 0 | L12: =VLOOKUP(A6,ESSALUD!$B$1:$G$19,6,FALSE) -> 442.26 | W12: 1077485287 | X12: 655610ZCBIT4 | Y12: 77485287
A13: D013 AUXILIO DE MOVILIDAD | C13: =SUMIF(Dev!$B:$B,CONCATENATE($A$6,A13),Dev!$L:$L) -> 0 | D13: =SUMIF(Dev!$B:$B,CONCATENATE($A$6,A13),Dev!M:M) -> 36 | E13: I200 SOBREVIVENCIA AFP | G13: =SUMIF(Dev!$B:$B,CONCATENATE($A$6,E13),Dev!$L:$L) -> 0 | H13: =SUMIF(Dev!$B:$B,CONCATENATE($A$6,E13),Dev!N:N) -> 89.76 | I13: CREDITO EPS | K13: 0 | L13: =VLOOKUP(A6,ESSALUD!$B$1:$H$19,7,FALSE) -> 147.42 | W13: 2001252358 | X13: 627991JMXQX0 | Y13: 001252358
A14: G006 VACACIONES | C14: =SUMIF(Dev!$B:$B,CONCATENATE($A$6,A14),Dev!$L:$L) -> 96 | D14: =SUMIF(Dev!$B:$B,CONCATENATE($A$6,A14),Dev!M:M) -> 2620.8 | E14: R000 RETENCION IMPUESTO A LA RENTA | G14: =SUMIF(Dev!$B:$B,CONCATENATE($A$6,#REF!),Dev!$L:$L) -> 0 | H14: =SUMIF(Dev!$B:$B,CONCATENATE($A$6,E14),Dev!N:N) -> 501.01 | W14: 42115329 | X14: FACILITIES | Y14: 42115329
W15: 42683912 | X15: 309631GHMAI4 | Y15: 42683912
W16: 72836862 | X16: 663680JMDIO1 | Y16: 72836862
W17: 76607245 | X17: N/A | Y17: 76607245
W18: 74026184 | X18: N/A | Y18: 74026184
I25: TOTAL APORTE EMPLEADOR | L25: =SUM(L12:L24) -> 589.68
A26: REMUNERACION TOTAL | D26: =SUM(D12:D24) -> 6588 | E26: DESCUENTOS TOTALES | H26: =SUM(H12:H24) -> 1245.97 | I26: REMUNERACION NETA | L26: =+D26-H26 -> 5342.03
F36: REPRESENTANTE LEGAL | J36: RECIBI CONFORME TRABAJADOR

Sheet PS1 (6)
A1: BOLETA DE PAGO | W1: EMPLEADO | X1: # AG ESSALUD | Y1: CODIGO EMPRESA
A2: EMPRESA | B2: CLARKE, MODET & CO. PERU S.A.C. | E2: R.U.C. | F2: 20256396000 | G2: MES | H2: =Detallado!R2 -> 05 | I2: AÑO | J2: =Detallado!S2 -> 2026 | K2: F. INGRESO | L2: =VLOOKUP(A6,'BD Total'!$A$2:$EZ$17,11,FALSE) -> 44151 | O2: # | P2: 1 | W2: 1007874085 | X2: 260130RRCOI9 | Y2: 07874085
E3: PERIODO | F3: =VLOOKUP($A$6,Detallado!$C:$U,16,FALSE) -> 05 | G3: DEL | H3: =VLOOKUP($A$6,Detallado!$C:$U,18,FALSE) -> 01/05/2026 | I3: AL | J3: =VLOOKUP($A$6,Detallado!$C:$U,19,FALSE) -> 46173 | K3: F. RETIRO | W3: 1040703418 | X3: 595200FCCCA8 | Y3: 40703418
W4: 1044771836 | X4: 621441RFSRR2 | Y4: 44771836
A5: CÓDIGO | B5: NOMBRES Y APELLIDOS | E5: CARGO | I5: AREA | W5: 1045191394 | X5: 322431AABAT4 | Y5: 45191394
A6: 1046722547 | B6: =VLOOKUP(A6,Dev!$C$1:$D$78,2,FALSE) -> FELIX ALEJANDRO KOO RIOJA | E6: =VLOOKUP(A6,'BD Total'!$A$2:$EZ$18,77,FALSE) -> FINANCE & ACCOUNTING SPECIALIST | I6: =VLOOKUP(A6,'BD Total'!$A$2:$EZ$18,81,FALSE) -> FINANZAS | W6: 1046129072 | X6: 628890LLCAD9 | Y6: 46129072
A7: D.N.I. | B7: CUSPP AFP | C7: # AG ESSALUD | E7: SALARIO | G7: MONEDA | I7: CODIGO EMPRESA | K7: A.F.P. | W7: 1046722547 | X7: 632311FKROJ0 | Y7: 46722547
A8: =VLOOKUP(A6,'BD Total'!$A$2:$EZ$18,2,FALSE) -> 46722547 | B8: =VLOOKUP(A6,'BD Total'!$A$2:$EZ$18,85,FALSE) -> 632311FKROJ0 | C8: =VLOOKUP(A6,$W$1:$Y$20,2,FALSE) -> 632311FKROJ0 | E8: =VLOOKUP(A6,'BD Total'!$A$2:$EZ$18,22,FALSE) -> 5733 | G8: SOL | I8: =VLOOKUP(A6,$W$1:$Y$20,3,FALSE) -> 46722547 | K8: =VLOOKUP(A6,'BD Total'!$A$2:$EZ$18,101,FALSE) -> INTEGRA | W8: 1047924040 | X8: 641640MNERI3 | Y8: 47924040
W9: 1070165336 | X9: 640621VFCNT9 | Y9: 70165336
A10: REMUNERACIONES | E10: DESCUENTOS TRABAJADOR | I10: APORTACIONES EMPLEADOR | W10: 1070680748 | X10: 0 | Y10: 70680748
A11: CONCEPTO | C11: HORAS | D11: VALOR | E11: CONCEPTO | G11: HORAS | H11: VALOR | I11: CONCEPTO | K11: HORAS | L11: VALOR | W11: 1072251509 | X11: 631390CHTMR2 | Y11: 72251509
A12: A000 SUELDO BASICO | C12: =SUMIF(Dev!$B:$B,CONCATENATE($A$6,A12),Dev!$L:$L) -> 128 | D12: =SUMIF(Dev!$B:$B,CONCATENATE($A$6,A12),Dev!M:M) -> 3057.6 | E12: I100 APORTE OBLIGATORIO AFP | G12: =SUMIF(Dev!$B:$B,CONCATENATE($A$6,E12),Dev!$L:$L) -> 0 | H12: =SUMIF(Dev!$B:$B,CONCATENATE($A$6,E12),Dev!N:N) -> 573.3 | I12: APORTE A ESSALUD | K12: 0 | L12: =VLOOKUP(A6,ESSALUD!$B$1:$G$19,6,FALSE) -> 386.9775 | W12: 1077485287 | X12: 655610ZCBIT4 | Y12: 77485287
A13: G006 VACACIONES | C13: =SUMIF(Dev!$B:$B,CONCATENATE($A$6,A13),Dev!$L:$L) -> 112 | D13: =SUMIF(Dev!$B:$B,CONCATENATE($A$6,A13),Dev!M:M) -> 2675.4 | E13: I200 SOBREVIVENCIA AFP | G13: =SUMIF(Dev!$B:$B,CONCATENATE($A$6,E13),Dev!$L:$L) -> 0 | H13: =SUMIF(Dev!$B:$B,CONCATENATE($A$6,E13),Dev!N:N) -> 78.54 | I13: CREDITO EPS | K13: 0 | L13: =VLOOKUP(A6,ESSALUD!$B$1:$H$19,7,FALSE) -> 128.9925 | W13: 2001252358 | X13: 627991JMXQX0 | Y13: 001252358
E14: R000 RETENCION IMPUESTO A LA RENTA | G14: =SUMIF(Dev!$B:$B,CONCATENATE($A$6,#REF!),Dev!$L:$L) -> 0 | H14: =SUMIF(Dev!$B:$B,CONCATENATE($A$6,E14),Dev!N:N) -> 363.08 | W14: 42115329 | X14: FACILITIES | Y14: 42115329
W15: 42683912 | X15: 309631GHMAI4 | Y15: 42683912
W16: 72836862 | X16: 663680JMDIO1 | Y16: 72836862
W17: 76607245 | X17: N/A | Y17: 76607245
W18: 74026184 | X18: N/A | Y18: 74026184
I25: TOTAL APORTE EMPLEADOR | L25: =SUM(L12:L24) -> 515.97
A26: REMUNERACION TOTAL | D26: =SUM(D12:D24) -> 5733 | E26: DESCUENTOS TOTALES | H26: =SUM(H12:H24) -> 1014.92 | I26: REMUNERACION NETA | L26: =+D26-H26 -> 4718.08
F36: REPRESENTANTE LEGAL | J36: RECIBI CONFORME TRABAJADOR

Sheet PS1 (5)
A1: BOLETA DE PAGO | W1: EMPLEADO | X1: # AG ESSALUD | Y1: CODIGO EMPRESA
A2: EMPRESA | B2: CLARKE, MODET & CO. PERU S.A.C. | E2: R.U.C. | F2: 20256396000 | G2: MES | H2: =Detallado!R2 -> 05 | I2: AÑO | J2: =Detallado!S2 -> 2026 | K2: F. INGRESO | L2: =VLOOKUP(A6,'BD Total'!$A$2:$EZ$17,11,FALSE) -> 42765 | O2: # | P2: 1 | W2: 1007874085 | X2: 260130RRCOI9 | Y2: 07874085
E3: PERIODO | F3: =VLOOKUP($A$6,Detallado!$C:$U,16,FALSE) -> 05 | G3: DEL | H3: =VLOOKUP($A$6,Detallado!$C:$U,18,FALSE) -> 01/05/2026 | I3: AL | J3: =VLOOKUP($A$6,Detallado!$C:$U,19,FALSE) -> 46173 | K3: F. RETIRO | W3: 1040703418 | X3: 595200FCCCA8 | Y3: 40703418
W4: 1044771836 | X4: 621441RFSRR2 | Y4: 44771836
A5: CÓDIGO | B5: NOMBRES Y APELLIDOS | E5: CARGO | I5: AREA | W5: 1045191394 | X5: 322431AABAT4 | Y5: 45191394
A6: 1046129072 | B6: =VLOOKUP(A6,Dev!$C$1:$D$78,2,FALSE) -> LAURA CAROLINA LIRA CANDIA | E6: =VLOOKUP(A6,'BD Total'!$A$2:$EZ$18,77,FALSE) -> IP PROSECUTION SPECIALIST | I6: =VLOOKUP(A6,'BD Total'!$A$2:$EZ$18,81,FALSE) -> CENTRAL SERVICES | W6: 1046129072 | X6: 628890LLCAD9 | Y6: 46129072
A7: D.N.I. | B7: CUSPP AFP | C7: # AG ESSALUD | E7: SALARIO | G7: MONEDA | I7: CODIGO EMPRESA | K7: A.F.P. | W7: 1046722547 | X7: 632311FKROJ0 | Y7: 46722547
A8: =VLOOKUP(A6,'BD Total'!$A$2:$EZ$18,2,FALSE) -> 46129072 | B8: =VLOOKUP(A6,'BD Total'!$A$2:$EZ$18,85,FALSE) -> 628890LLCAD9 | C8: =VLOOKUP(A6,$W$1:$Y$20,2,FALSE) -> 628890LLCAD9 | E8: =VLOOKUP(A6,'BD Total'!$A$2:$EZ$18,22,FALSE) -> 3871 | G8: SOL | I8: =VLOOKUP(A6,$W$1:$Y$20,3,FALSE) -> 46129072 | K8: =VLOOKUP(A6,'BD Total'!$A$2:$EZ$18,101,FALSE) -> HABITAT | W8: 1047924040 | X8: 641640MNERI3 | Y8: 47924040
W9: 1070165336 | X9: 640621VFCNT9 | Y9: 70165336
A10: REMUNERACIONES | E10: DESCUENTOS TRABAJADOR | I10: APORTACIONES EMPLEADOR | W10: 1070680748 | X10: 0 | Y10: 70680748
A11: CONCEPTO | C11: HORAS | D11: VALOR | E11: CONCEPTO | G11: HORAS | H11: VALOR | I11: CONCEPTO | K11: HORAS | L11: VALOR | W11: 1072251509 | X11: 631390CHTMR2 | Y11: 72251509
A12: A000 SUELDO BASICO | C12: =SUMIF(Dev!$B:$B,CONCATENATE($A$6,A12),Dev!$L:$L) -> 184 | D12: =SUMIF(Dev!$B:$B,CONCATENATE($A$6,A12),Dev!M:M) -> 2967.77 | E12: I100 APORTE OBLIGATORIO AFP | G12: =SUMIF(Dev!$B:$B,CONCATENATE($A$6,E12),Dev!$L:$L) -> 0 | H12: =SUMIF(Dev!$B:$B,CONCATENATE($A$6,E12),Dev!N:N) -> 387.1 | I12: APORTE A ESSALUD | K12: 0 | L12: =VLOOKUP(A6,ESSALUD!$B$1:$G$19,6,FALSE) -> 261.2925 | W12: 1077485287 | X12: 655610ZCBIT4 | Y12: 77485287
A13: D013 AUXILIO DE MOVILIDAD | C13: =SUMIF(Dev!$B:$B,CONCATENATE($A$6,A13),Dev!$L:$L) -> 0 | D13: =SUMIF(Dev!$B:$B,CONCATENATE($A$6,A13),Dev!M:M) -> 36 | E13: I200 SOBREVIVENCIA AFP | G13: =SUMIF(Dev!$B:$B,CONCATENATE($A$6,E13),Dev!$L:$L) -> 0 | H13: =SUMIF(Dev!$B:$B,CONCATENATE($A$6,E13),Dev!N:N) -> 53.03 | I13: CREDITO EPS | K13: 0 | L13: =VLOOKUP(A6,ESSALUD!$B$1:$H$19,7,FALSE) -> 87.0975 | W13: 2001252358 | X13: 627991JMXQX0 | Y13: 001252358
A14: G006 VACACIONES | C14: =SUMIF(Dev!$B:$B,CONCATENATE($A$6,A14),Dev!$L:$L) -> 56 | D14: =SUMIF(Dev!$B:$B,CONCATENATE($A$6,A14),Dev!M:M) -> 903.23 | E14: R000 RETENCION IMPUESTO A LA RENTA | G14: =SUMIF(Dev!$B:$B,CONCATENATE($A$6,#REF!),Dev!$L:$L) -> 0 | H14: =SUMIF(Dev!$B:$B,CONCATENATE($A$6,E14),Dev!N:N) -> 109.98 | W14: 42115329 | X14: FACILITIES | Y14: 42115329
W15: 42683912 | X15: 309631GHMAI4 | Y15: 42683912
W16: 72836862 | X16: 663680JMDIO1 | Y16: 72836862
W17: 76607245 | X17: N/A | Y17: 76607245
W18: 74026184 | X18: N/A | Y18: 74026184
I25: TOTAL APORTE EMPLEADOR | L25: =SUM(L12:L24) -> 348.39
A26: REMUNERACION TOTAL | D26: =SUM(D12:D24) -> 3907 | E26: DESCUENTOS TOTALES | H26: =SUM(H12:H24) -> 550.11 | I26: REMUNERACION NETA | L26: =+D26-H26 -> 3356.89
F36: REPRESENTANTE LEGAL | J36: RECIBI CONFORME TRABAJADOR

Sheet PS1 (4)
A1: BOLETA DE PAGO | W1: EMPLEADO | X1: # AG ESSALUD | Y1: CODIGO EMPRESA
A2: EMPRESA | B2: CLARKE, MODET & CO. PERU S.A.C. | E2: R.U.C. | F2: 20256396000 | G2: MES | H2: =Detallado!R2 -> 05 | I2: AÑO | J2: =Detallado!S2 -> 2026 | K2: F. INGRESO | L2: =VLOOKUP(A6,'BD Total'!$A$2:$EZ$17,11,FALSE) -> 42989 | O2: # | P2: 1 | W2: 1007874085 | X2: 260130RRCOI9 | Y2: 07874085
E3: PERIODO | F3: =VLOOKUP($A$6,Detallado!$C:$U,16,FALSE) -> 05 | G3: DEL | H3: =VLOOKUP($A$6,Detallado!$C:$U,18,FALSE) -> 01/05/2026 | I3: AL | J3: =VLOOKUP($A$6,Detallado!$C:$U,19,FALSE) -> 46173 | K3: F. RETIRO | W3: 1040703418 | X3: 595200FCCCA8 | Y3: 40703418
W4: 1044771836 | X4: 621441RFSRR2 | Y4: 44771836
A5: CÓDIGO | B5: NOMBRES Y APELLIDOS | E5: CARGO | I5: AREA | W5: 1045191394 | X5: 322431AABAT4 | Y5: 45191394
A6: 1045191394 | B6: =VLOOKUP(A6,Dev!$C$1:$D$78,2,FALSE) -> ALVARO JAVIER ARIAS BAUTISTA | E6: =VLOOKUP(A6,'BD Total'!$A$2:$EZ$18,77,FALSE) -> COUNTRY MANAGING DIRECTOR | I6: =VLOOKUP(A6,'BD Total'!$A$2:$EZ$18,81,FALSE) -> CEO | W6: 1046129072 | X6: 628890LLCAD9 | Y6: 46129072
A7: D.N.I. | B7: CUSPP AFP | C7: # AG ESSALUD | E7: SALARIO | G7: MONEDA | I7: CODIGO EMPRESA | K7: A.F.P. | W7: 1046722547 | X7: 632311FKROJ0 | Y7: 46722547
A8: =VLOOKUP(A6,'BD Total'!$A$2:$EZ$18,2,FALSE) -> 45191394 | B8: =VLOOKUP(A6,'BD Total'!$A$2:$EZ$18,85,FALSE) -> 322431AABAT4 | C8: =VLOOKUP(A6,$W$1:$Y$20,2,FALSE) -> 322431AABAT4 | E8: =VLOOKUP(A6,'BD Total'!$A$2:$EZ$18,22,FALSE) -> 14615 | G8: SOL | I8: =VLOOKUP(A6,$W$1:$Y$20,3,FALSE) -> 45191394 | K8: =VLOOKUP(A6,'BD Total'!$A$2:$EZ$18,101,FALSE) -> PROFUTURO | W8: 1047924040 | X8: 641640MNERI3 | Y8: 47924040
W9: 1070165336 | X9: 640621VFCNT9 | Y9: 70165336
A10: REMUNERACIONES | E10: DESCUENTOS TRABAJADOR | I10: APORTACIONES EMPLEADOR | W10: 1070680748 | X10: 0 | Y10: 70680748
A11: CONCEPTO | C11: HORAS | D11: VALOR | E11: CONCEPTO | G11: HORAS | H11: VALOR | I11: CONCEPTO | K11: HORAS | L11: VALOR | W11: 1072251509 | X11: 631390CHTMR2 | Y11: 72251509
A12: A000 SUELDO BASICO | C12: =SUMIF(Dev!$B:$B,CONCATENATE($A$6,A12),Dev!$L:$L) -> 240 | D12: =SUMIF(Dev!$B:$B,CONCATENATE($A$6,A12),Dev!M:M) -> 14615 | E12: I100 APORTE OBLIGATORIO AFP | G12: =SUMIF(Dev!$B:$B,CONCATENATE($A$6,E12),Dev!$L:$L) -> 0 | H12: =SUMIF(Dev!$B:$B,CONCATENATE($A$6,E12),Dev!N:N) -> 1461.5 | I12: APORTE A ESSALUD | K12: 0 | L12: =VLOOKUP(A6,ESSALUD!$B$1:$G$19,6,FALSE) -> 986.5125 | W12: 1077485287 | X12: 655610ZCBIT4 | Y12: 77485287
E13: I200 SOBREVIVENCIA AFP | G13: =SUMIF(Dev!$B:$B,CONCATENATE($A$6,E13),Dev!$L:$L) -> 0 | H13: =SUMIF(Dev!$B:$B,CONCATENATE($A$6,E13),Dev!N:N) -> 172.61 | I13: CREDITO EPS | K13: 0 | L13: =VLOOKUP(A6,ESSALUD!$B$1:$H$19,7,FALSE) -> 328.8375 | W13: 2001252358 | X13: 627991JMXQX0 | Y13: 001252358
E14: R000 RETENCION IMPUESTO A LA RENTA | G14: =SUMIF(Dev!$B:$B,CONCATENATE($A$6,#REF!),Dev!$L:$L) -> 0 | H14: =SUMIF(Dev!$B:$B,CONCATENATE($A$6,E14),Dev!N:N) -> 1972.88 | W14: 42115329 | X14: FACILITIES | Y14: 42115329
W15: 42683912 | X15: 309631GHMAI4 | Y15: 42683912
W16: 72836862 | X16: 663680JMDIO1 | Y16: 72836862
W17: 76607245 | X17: N/A | Y17: 76607245
W18: 74026184 | X18: N/A | Y18: 74026184
I25: TOTAL APORTE EMPLEADOR | L25: =SUM(L12:L24) -> 1315.35
A26: REMUNERACION TOTAL | D26: =SUM(D12:D24) -> 14615 | E26: DESCUENTOS TOTALES | H26: =SUM(H12:H24) -> 3606.99 | I26: REMUNERACION NETA | L26: =+D26-H26 -> 11008.01
F36: REPRESENTANTE LEGAL | J36: RECIBI CONFORME TRABAJADOR

Sheet PS1 (3)
A1: BOLETA DE PAGO | W1: EMPLEADO | X1: # AG ESSALUD | Y1: CODIGO EMPRESA
A2: EMPRESA | B2: CLARKE, MODET & CO. PERU S.A.C. | E2: R.U.C. | F2: 20256396000 | G2: MES | H2: =Detallado!R2 -> 05 | I2: AÑO | J2: =Detallado!S2 -> 2026 | K2: F. INGRESO | L2: =VLOOKUP(A6,'BD Total'!$A$2:$EZ$17,11,FALSE) -> 42506 | O2: # | P2: 1 | W2: 1007874085 | X2: 260130RRCOI9 | Y2: 07874085
E3: PERIODO | F3: =VLOOKUP($A$6,Detallado!$C:$U,16,FALSE) -> 05 | G3: DEL | H3: =VLOOKUP($A$6,Detallado!$C:$U,18,FALSE) -> 01/05/2026 | I3: AL | J3: =VLOOKUP($A$6,Detallado!$C:$U,19,FALSE) -> 46173 | K3: F. RETIRO | W3: 1040703418 | X3: 595200FCCCA8 | Y3: 40703418
W4: 1044771836 | X4: 621441RFSRR2 | Y4: 44771836
A5: CÓDIGO | B5: NOMBRES Y APELLIDOS | E5: CARGO | I5: AREA | W5: 1045191394 | X5: 322431AABAT4 | Y5: 45191394
A6: 1044771836 | B6: =VLOOKUP(A6,Dev!$C$1:$D$78,2,FALSE) -> RONALD FLOREZ SUAREZ | E6: =VLOOKUP(A6,'BD Total'!$A$2:$EZ$18,77,FALSE) -> IP PROSECUTION SPECIALIST | I6: =VLOOKUP(A6,'BD Total'!$A$2:$EZ$18,81,FALSE) -> INVENTIONS | W6: 1046129072 | X6: 628890LLCAD9 | Y6: 46129072
A7: D.N.I. | B7: CUSPP AFP | C7: # AG ESSALUD | E7: SALARIO | G7: MONEDA | I7: CODIGO EMPRESA | K7: A.F.P. | W7: 1046722547 | X7: 632311FKROJ0 | Y7: 46722547
A8: =VLOOKUP(A6,'BD Total'!$A$2:$EZ$18,2,FALSE) -> 44771836 | B8: =VLOOKUP(A6,'BD Total'!$A$2:$EZ$18,85,FALSE) -> 621441RFSRR2 | C8: =VLOOKUP(A6,$W$1:$Y$20,2,FALSE) -> 621441RFSRR2 | E8: =VLOOKUP(A6,'BD Total'!$A$2:$EZ$18,22,FALSE) -> 8842 | G8: SOL | I8: =VLOOKUP(A6,$W$1:$Y$20,3,FALSE) -> 44771836 | K8: =VLOOKUP(A6,'BD Total'!$A$2:$EZ$18,101,FALSE) -> PROFUTURO | W8: 1047924040 | X8: 641640MNERI3 | Y8: 47924040
W9: 1070165336 | X9: 640621VFCNT9 | Y9: 70165336
A10: REMUNERACIONES | E10: DESCUENTOS TRABAJADOR | I10: APORTACIONES EMPLEADOR | W10: 1070680748 | X10: 0 | Y10: 70680748
A11: CONCEPTO | C11: HORAS | D11: VALOR | E11: CONCEPTO | G11: HORAS | H11: VALOR | I11: CONCEPTO | K11: HORAS | L11: VALOR | W11: 1072251509 | X11: 631390CHTMR2 | Y11: 72251509
A12: A000 SUELDO BASICO | C12: =SUMIF(Dev!$B:$B,CONCATENATE($A$6,A12),Dev!$L:$L) -> 184 | D12: =SUMIF(Dev!$B:$B,CONCATENATE($A$6,A12),Dev!M:M) -> 6778.87 | E12: I100 APORTE OBLIGATORIO AFP | G12: =SUMIF(Dev!$B:$B,CONCATENATE($A$6,E12),Dev!$L:$L) -> 0 | H12: =SUMIF(Dev!$B:$B,CONCATENATE($A$6,E12),Dev!N:N) -> 884.2 | I12: APORTE A ESSALUD | K12: 0 | L12: =VLOOKUP(A6,ESSALUD!$B$1:$G$19,6,FALSE) -> 596.835 | W12: 1077485287 | X12: 655610ZCBIT4 | Y12: 77485287
A13: G006 VACACIONES | C13: =SUMIF(Dev!$B:$B,CONCATENATE($A$6,A13),Dev!$L:$L) -> 56 | D13: =SUMIF(Dev!$B:$B,CONCATENATE($A$6,A13),Dev!M:M) -> 2063.13 | E13: I200 SOBREVIVENCIA AFP | G13: =SUMIF(Dev!$B:$B,CONCATENATE($A$6,E13),Dev!$L:$L) -> 0 | H13: =SUMIF(Dev!$B:$B,CONCATENATE($A$6,E13),Dev!N:N) -> 121.14 | I13: CREDITO EPS | K13: 0 | L13: =VLOOKUP(A6,ESSALUD!$B$1:$H$19,7,FALSE) -> 198.945 | W13: 2001252358 | X13: 627991JMXQX0 | Y13: 001252358
E14: I300 COMISION VARIABLE AFP | G14: =SUMIF(Dev!$B:$B,CONCATENATE($A$6,E14),Dev!$L:$L) -> 0 | H14: =SUMIF(Dev!$B:$B,CONCATENATE($A$6,E14),Dev!N:N) -> 149.43 | W14: 42115329 | X14: FACILITIES | Y14: 42115329
E15: R000 RETENCION IMPUESTO A LA RENTA | G15: =SUMIF(Dev!$B:$B,CONCATENATE($A$6,E15),Dev!$L:$L) -> 0 | H15: =SUMIF(Dev!$B:$B,CONCATENATE($A$6,E15),Dev!N:N) -> 871.57 | W15: 42683912 | X15: 309631GHMAI4 | Y15: 42683912
W16: 72836862 | X16: 663680JMDIO1 | Y16: 72836862
W17: 76607245 | X17: N/A | Y17: 76607245
W18: 74026184 | X18: N/A | Y18: 74026184
I25: TOTAL APORTE EMPLEADOR | L25: =SUM(L12:L24) -> 795.78
A26: REMUNERACION TOTAL | D26: =SUM(D12:D24) -> 8842 | E26: DESCUENTOS TOTALES | H26: =SUM(H12:H24) -> 2026.34 | I26: REMUNERACION NETA | L26: =+D26-H26 -> 6815.66
F36: REPRESENTANTE LEGAL | J36: RECIBI CONFORME TRABAJADOR

Sheet PS1 (2)
A1: BOLETA DE PAGO | W1: EMPLEADO | X1: # AG ESSALUD | Y1: CODIGO EMPRESA
A2: EMPRESA | B2: CLARKE, MODET & CO. PERU S.A.C. | E2: R.U.C. | F2: 20256396000 | G2: MES | H2: =Detallado!R2 -> 05 | I2: AÑO | J2: =Detallado!S2 -> 2026 | K2: F. INGRESO | L2: =VLOOKUP(A6,'BD Total'!$A$2:$EZ$17,11,FALSE) -> 42257 | O2: # | P2: 1 | W2: 1007874085 | X2: 260130RRCOI9 | Y2: 07874085
E3: PERIODO | F3: =VLOOKUP($A$6,Detallado!$C:$U,16,FALSE) -> 05 | G3: DEL | H3: =VLOOKUP($A$6,Detallado!$C:$U,18,FALSE) -> 01/05/2026 | I3: AL | J3: =VLOOKUP($A$6,Detallado!$C:$U,19,FALSE) -> 46173 | K3: F. RETIRO | W3: 1040703418 | X3: 595200FCCCA8 | Y3: 40703418
W4: 1044771836 | X4: 621441RFSRR2 | Y4: 44771836
A5: CÓDIGO | B5: NOMBRES Y APELLIDOS | E5: CARGO | I5: AREA | W5: 1045191394 | X5: 322431AABAT4 | Y5: 45191394
A6: 1040703418 | B6: =VLOOKUP(A6,Dev!$C$1:$D$78,2,FALSE) -> FIORELLA GIOVANNA CHICHIZOLA CANALE | E6: =VLOOKUP(A6,'BD Total'!$A$2:$EZ$18,77,FALSE) -> IP PROSECUTION SPECIALIST | I6: =VLOOKUP(A6,'BD Total'!$A$2:$EZ$18,81,FALSE) -> CENTRAL SERVICES | W6: 1046129072 | X6: 628890LLCAD9 | Y6: 46129072
A7: D.N.I. | B7: CUSPP AFP | C7: # AG ESSALUD | E7: SALARIO | G7: MONEDA | I7: CODIGO EMPRESA | K7: A.F.P. | W7: 1046722547 | X7: 632311FKROJ0 | Y7: 46722547
A8: =VLOOKUP(A6,'BD Total'!$A$2:$EZ$18,2,FALSE) -> 40703418 | B8: =VLOOKUP(A6,'BD Total'!$A$2:$EZ$18,85,FALSE) -> 595200FCCCA8 | C8: =VLOOKUP(A6,$W$1:$Y$20,2,FALSE) -> 595200FCCCA8 | E8: =VLOOKUP(A6,'BD Total'!$A$2:$EZ$18,22,FALSE) -> 3700 | G8: SOL | I8: =VLOOKUP(A6,$W$1:$Y$20,3,FALSE) -> 40703418 | K8: =VLOOKUP(A6,'BD Total'!$A$2:$EZ$18,101,FALSE) -> INTEGRA | W8: 1047924040 | X8: 641640MNERI3 | Y8: 47924040
W9: 1070165336 | X9: 640621VFCNT9 | Y9: 70165336
A10: REMUNERACIONES | E10: DESCUENTOS TRABAJADOR | I10: APORTACIONES EMPLEADOR | W10: 1070680748 | X10: 0 | Y10: 70680748
A11: CONCEPTO | C11: HORAS | D11: VALOR | E11: CONCEPTO | G11: HORAS | H11: VALOR | I11: CONCEPTO | K11: HORAS | L11: VALOR | W11: 1072251509 | X11: 631390CHTMR2 | Y11: 72251509
A12: A000 SUELDO BASICO | C12: =SUMIF(Dev!$B:$B,CONCATENATE($A$6,A12),Dev!$L:$L) -> 216 | D12: =SUMIF(Dev!$B:$B,CONCATENATE($A$6,A12),Dev!M:M) -> 3330 | E12: I100 APORTE OBLIGATORIO AFP | G12: =SUMIF(Dev!$B:$B,CONCATENATE($A$6,E12),Dev!$L:$L) -> 0 | H12: =SUMIF(Dev!$B:$B,CONCATENATE($A$6,E12),Dev!N:N) -> 370 | I12: APORTE A ESSALUD | K12: 0 | L12: =VLOOKUP(A6,ESSALUD!$B$1:$G$19,6,FALSE) -> 249.75 | W12: 1077485287 | X12: 655610ZCBIT4 | Y12: 77485287
A13: D013 AUXILIO DE MOVILIDAD | C13: =SUMIF(Dev!$B:$B,CONCATENATE($A$6,A13),Dev!$L:$L) -> 0 | D13: =SUMIF(Dev!$B:$B,CONCATENATE($A$6,A13),Dev!M:M) -> 24 | E13: I200 SOBREVIVENCIA AFP | G13: =SUMIF(Dev!$B:$B,CONCATENATE($A$6,E13),Dev!$L:$L) -> 0 | H13: =SUMIF(Dev!$B:$B,CONCATENATE($A$6,E13),Dev!N:N) -> 50.69 | I13: CREDITO EPS | K13: 0 | L13: =VLOOKUP(A6,ESSALUD!$B$1:$H$19,7,FALSE) -> 83.25 | W13: 2001252358 | X13: 627991JMXQX0 | Y13: 001252358
A14: B100 DESCANSO MEDICO | C14: =SUMIF(Dev!$B:$B,CONCATENATE($A$6,A14),Dev!$L:$L) -> 24 | D14: =SUMIF(Dev!$B:$B,CONCATENATE($A$6,A14),Dev!M:M) -> 370 | E14: I300 COMISION VARIABLE AFP | G14: =SUMIF(Dev!$B:$B,CONCATENATE($A$6,E14),Dev!$L:$L) -> 0 | H14: =SUMIF(Dev!$B:$B,CONCATENATE($A$6,E14),Dev!N:N) -> 57.35 | W14: 42115329 | X14: FACILITIES | Y14: 42115329
E15: R000 RETENCION IMPUESTO A LA RENTA | G15: =SUMIF(Dev!$B:$B,CONCATENATE($A$6,E15),Dev!$L:$L) -> 0 | H15: =SUMIF(Dev!$B:$B,CONCATENATE($A$6,E15),Dev!N:N) -> 93.85 | W15: 42683912 | X15: 309631GHMAI4 | Y15: 42683912
W16: 72836862 | X16: 663680JMDIO1 | Y16: 72836862
W17: 76607245 | X17: N/A | Y17: 76607245
W18: 74026184 | X18: N/A | Y18: 74026184
I25: TOTAL APORTE EMPLEADOR | L25: =SUM(L12:L24) -> 333
A26: REMUNERACION TOTAL | D26: =SUM(D12:D24) -> 3724 | E26: DESCUENTOS TOTALES | H26: =SUM(H12:H24) -> 571.89 | I26: REMUNERACION NETA | L26: =+D26-H26 -> 3152.11
F36: REPRESENTANTE LEGAL | J36: RECIBI CONFORME TRABAJADOR

Sheet PS1
A1: BOLETA DE PAGO | W1: EMPLEADO | X1: # AG ESSALUD | Y1: CODIGO EMPRESA
A2: EMPRESA | B2: CLARKE, MODET & CO. PERU S.A.C. | E2: R.U.C. | F2: 20256396000 | G2: MES | H2: =Detallado!R2 -> 05 | I2: AÑO | J2: =Detallado!S2 -> 2026 | K2: F. INGRESO | L2: =VLOOKUP(A6,'BD Total'!$A$2:$EZ$17,11,FALSE) -> 44348 | O2: # | P2: 1 | W2: 1007874085 | X2: 260130RRCOI9 | Y2: 07874085
E3: PERIODO | F3: =VLOOKUP($A$6,Detallado!$C:$U,16,FALSE) -> 05 | G3: DEL | H3: =VLOOKUP($A$6,Detallado!$C:$U,18,FALSE) -> 01/05/2026 | I3: AL | J3: =VLOOKUP($A$6,Detallado!$C:$U,19,FALSE) -> 46173 | K3: F. RETIRO | W3: 1040703418 | X3: 595200FCCCA8 | Y3: 40703418
W4: 1044771836 | X4: 621441RFSRR2 | Y4: 44771836
A5: CÓDIGO | B5: NOMBRES Y APELLIDOS | E5: CARGO | I5: AREA | W5: 1045191394 | X5: 322431AABAT4 | Y5: 45191394
A6: 1007874085 | B6: =VLOOKUP(A6,Dev!$C$1:$D$78,2,FALSE) -> ROCIO DE LOURDES RAMOS CORI | E6: =VLOOKUP(A6,'BD Total'!$A$2:$EZ$18,77,FALSE) -> IP PROSECUTION SPECIALIST | I6: =VLOOKUP(A6,'BD Total'!$A$2:$EZ$18,81,FALSE) -> CENTRAL SERVICES | W6: 1046129072 | X6: 628890LLCAD9 | Y6: 46129072
A7: D.N.I. | B7: CUSPP AFP | C7: # AG ESSALUD | E7: SALARIO | G7: MONEDA | I7: CODIGO EMPRESA | K7: A.F.P. | W7: 1046722547 | X7: 632311FKROJ0 | Y7: 46722547
A8: =VLOOKUP(A6,'BD Total'!$A$2:$EZ$18,2,FALSE) -> 07874085 | B8: =VLOOKUP(A6,'BD Total'!$A$2:$EZ$18,85,FALSE) -> 260130RRCOI9 | C8: =VLOOKUP(A6,$W$1:$Y$20,2,FALSE) -> 260130RRCOI9 | E8: =VLOOKUP(A6,'BD Total'!$A$2:$EZ$18,22,FALSE) -> 3899 | G8: SOL | I8: =VLOOKUP(A6,$W$1:$Y$20,3,FALSE) -> 07874085 | K8: =VLOOKUP(A6,'BD Total'!$A$2:$EZ$18,101,FALSE) -> INTEGRA | W8: 1047924040 | X8: 641640MNERI3 | Y8: 47924040
W9: 1070165336 | X9: 640621VFCNT9 | Y9: 70165336
A10: REMUNERACIONES | E10: DESCUENTOS TRABAJADOR | I10: APORTACIONES EMPLEADOR | W10: 1070680748 | X10: 0 | Y10: 70680748
A11: CONCEPTO | C11: HORAS | D11: VALOR | E11: CONCEPTO | G11: HORAS | H11: VALOR | I11: CONCEPTO | K11: HORAS | L11: VALOR | W11: 1072251509 | X11: 631390CHTMR2 | Y11: 72251509
A12: A000 SUELDO BASICO | C12: =SUMIF(Dev!$B:$B,CONCATENATE($A$6,A12),Dev!$L:$L) -> 240 | D12: =SUMIF(Dev!$B:$B,CONCATENATE($A$6,A12),Dev!M:M) -> 3899 | E12: R000 RETENCION IMPUESTO A LA RENTA | G12: =SUMIF(Dev!$B:$B,CONCATENATE($A$6,E12),Dev!$L:$L) -> 0 | H12: =SUMIF(Dev!$B:$B,CONCATENATE($A$6,E12),Dev!N:N) -> 121.57 | I12: APORTE A ESSALUD | K12: 0 | L12: =VLOOKUP(A6,ESSALUD!$B$1:$G$19,6,FALSE) -> 270.81 | W12: 1077485287 | X12: 655610ZCBIT4 | Y12: 77485287
